Workbook

Sheet Reporte Diario
D2: DATOS REPORTE ASISTENCIA DIARIO
D3: PROYECTO: | E3: EIMI00359 | G3: =CONCATENATE("PROYECTO:"," ",_xlfn.XLOOKUP(E3,'Data obras'!B:B,'Data obras'!C:C,"Seleccionar Proyecto")) -> PROYECTO: OO.CC y Montaje Electromecánico MAPA Calderas
D4: FECHA ASISTENCIA: | E4: 46152
D5: CORREO A ENVIAR | E5: atapiab@eimontajes.cl
D6: VERSIÓN | E6: 0
B8: N° | C8: ROL | D8: RUT | E8: NOMBRE | F8: CARGO | G8: FECHA DE INGRESO | H8: JORNADA | I8: TURNO | J8: LUGAR DE TRABAJO | K8: ASISTENCIA | L8: UNIDAD | M8: TIPO MO | N8: GENERO | O8: REGIÓN | P8: CIUDAD | Q8: COMUNA | R8: TELEFONO

Sheet Resumen
D2: DATOS REPORTE ASISTENCIA DIARIO
D3: PROYECTO: | E3: ='Reporte Diario'!E3 -> EIMI00359 | G3: =CONCATENATE("RESUMEN REPORTE DIARIO PROYECTO",": ",_xlfn.XLOOKUP('Reporte Diario'!E3,'Data obras'!B:B,'Data obras'!C:C,"Seleccionar Proyecto")) -> RESUMEN REPORTE DIARIO PROYECTO: OO.CC y Montaje Electromecánico MAPA Calderas
D4: FECHA ASISTENCIA: | E4: =+'Reporte Diario'!E4 -> 46152
D5: VERSIÓN | E5: ='Reporte Diario'!E6 -> 0
Q7: TURNOS EN OBRA | U7: TURNOS EN DESCANSO
B9: ASISTENCIA | C9: OBRA | D9: DESCANSO | E9: LICENCIA MEDICA | F9: PERMISO C/S | G9: PERMISO S/S | H9: FALLA | I9: VACACIONES | J9: TELETRABAJO | K9: OFICINA SANTIAGO | L9: EN TRANSITO | M9: ACREDITADO | N9: TOTAL GENERAL | P9: TURNOS | Q9: 05x02 | R9: 08x06 | S9: 14x14 | T9: 15x13 | U9: 05x02 | V9: 08x06 | W9: 14x14 | X9: 15x13 | Y9: OTROS | Z9: TOTAL GENERAL
B10: MOD | C10: =SUM(C11:C21) -> 0 | D10: =SUM(D11:D21) -> 0 | E10: =SUM(E11:E21) -> 0 | F10: =SUM(F11:F21) -> 0 | G10: =SUM(G11:G21) -> 0 | H10: =SUM(H11:H21) -> 0 | I10: =SUM(I11:I21) -> 0 | J10: =SUM(J11:J21) -> 0 | ... N10: =SUM(N11:N21) -> 0 | P10: MOD | Q10: =SUM(Q11:Q22) -> 0 | R10: =SUM(R11:R22) -> 0 | S10: =SUM(S11:S22) -> 0 | T10: =SUM(T11:T22) -> 0 | U10: =SUM(U11:U22) -> 0 | V10: =SUM(V11:V22) -> 0 | W10: =SUM(W11:W22) -> 0 | X10: =SUM(X11:X22) -> 0 | Y10: =SUM(Y11:Y22) -> 0 | Z10: =SUM(Q10:Y10) -> 0
B11: ANDAMIOS | C11: =COUNTIFS('Reporte Diario'!$K:$K,Resumen!C$9,'Reporte Diario'!$L:$L,Resumen!$B11,'Reporte Diario'!$M:$M,Resumen!$B$10) -> 0 | D11: =COUNTIFS('Reporte Diario'!$K:$K,Resumen!D$9,'Reporte Diario'!$L:$L,Resumen!$B11,'Reporte Diario'!$M:$M,Resumen!$B$10) -> 0 | E11: =COUNTIFS('Reporte Diario'!$K:$K,Resumen!E$9,'Reporte Diario'!$L:$L,Resumen!$B11,'Reporte Diario'!$M:$M,Resumen!$B$10) -> 0 | F11: =COUNTIFS('Reporte Diario'!$K:$K,Resumen!F$9,'Reporte Diario'!$L:$L,Resumen!$B11,'Reporte Diario'!$M:$M,Resumen!$B$10) -> 0 | G11: =COUNTIFS('Reporte Diario'!$K:$K,Resumen!G$9,'Reporte Diario'!$L:$L,Resumen!$B11,'Reporte Diario'!$M:$M,Resumen!$B$10) -> 0 | H11: =COUNTIFS('Reporte Diario'!$K:$K,Resumen!H$9,'Reporte Diario'!$L:$L,Resumen!$B11,'Reporte Diario'!$M:$M,Resumen!$B$10) -> 0 | I11: =COUNTIFS('Reporte Diario'!$K:$K,Resumen!I$9,'Reporte Diario'!$L:$L,Resumen!$B11,'Reporte Diario'!$M:$M,Resumen!$B$10) -> 0 | J11: =COUNTIFS('Reporte Diario'!$K:$K,Resumen!J$9,'Reporte Diario'!$L:$L,Resumen!$B11,'Reporte Diario'!$M:$M,Resumen!$B$10) -> 0 | ... M11: =COUNTIFS('Reporte Diario'!$K:$K,Resumen!M$9,'Reporte Diario'!$L:$L,Resumen!$B11,'Reporte Diario'!$M:$M,Resumen!$B$10) -> 0 | N11: =SUM(C11:M11) -> 0 | P11: ANDAMIOS | Q11: =COUNTIFS('Reporte Diario'!$H:$H,Resumen!Q$9,'Reporte Diario'!$L:$L,$P11,'Reporte Diario'!$M:$M,$P$10,'Reporte Diario'!$K:$K,"OBRA") -> 0 | R11: =COUNTIFS('Reporte Diario'!$H:$H,Resumen!R$9,'Reporte Diario'!$L:$L,$P11,'Reporte Diario'!$M:$M,$P$10,'Reporte Diario'!$K:$K,"OBRA") -> 0 | S11: =COUNTIFS('Reporte Diario'!$H:$H,Resumen!S$9,'Reporte Diario'!$L:$L,$P11,'Reporte Diario'!$M:$M,$P$10,'Reporte Diario'!$K:$K,"OBRA") -> 0 | T11: =COUNTIFS('Reporte Diario'!$H:$H,Resumen!T$9,'Reporte Diario'!$L:$L,$P11,'Reporte Diario'!$M:$M,$P$10,'Reporte Diario'!$K:$K,"OBRA") -> 0 | U11: =COUNTIFS('Reporte Diario'!$H:$H,Resumen!U$9,'Reporte Diario'!$L:$L,$P11,'Reporte Diario'!$M:$M,$P$10,'Reporte Diario'!$K:$K,"DESCANSO") -> 0 | V11: =COUNTIFS('Reporte Diario'!$H:$H,Resumen!V$9,'Reporte Diario'!$L:$L,$P11,'Reporte Diario'!$M:$M,$P$10,'Reporte Diario'!$K:$K,"DESCANSO") -> 0 | W11: =COUNTIFS('Reporte Diario'!$H:$H,Resumen!W$9,'Reporte Diario'!$L:$L,$P11,'Reporte Diario'!$M:$M,$P$10,'Reporte Diario'!$K:$K,"DESCANSO") -> 0 | X11: =COUNTIFS('Reporte Diario'!$H:$H,Resumen!X$9,'Reporte Diario'!$L:$L,$P11,'Reporte Diario'!$M:$M,$P$10,'Reporte Diario'!$K:$K,"DESCANSO") -> 0 | Y11: =SUM(E11:M11) -> 0 | Z11: =SUM(Q11:Y11) -> 0
B12: AISLACIÓN | C12: =COUNTIFS('Reporte Diario'!$K:$K,Resumen!C$9,'Reporte Diario'!$L:$L,Resumen!$B12,'Reporte Diario'!$M:$M,Resumen!$B$10) -> 0 | D12: =COUNTIFS('Reporte Diario'!$K:$K,Resumen!D$9,'Reporte Diario'!$L:$L,Resumen!$B12,'Reporte Diario'!$M:$M,Resumen!$B$10) -> 0 | E12: =COUNTIFS('Reporte Diario'!$K:$K,Resumen!E$9,'Reporte Diario'!$L:$L,Resumen!$B12,'Reporte Diario'!$M:$M,Resumen!$B$10) -> 0 | F12: =COUNTIFS('Reporte Diario'!$K:$K,Resumen!F$9,'Reporte Diario'!$L:$L,Resumen!$B12,'Reporte Diario'!$M:$M,Resumen!$B$10) -> 0 | G12: =COUNTIFS('Reporte Diario'!$K:$K,Resumen!G$9,'Reporte Diario'!$L:$L,Resumen!$B12,'Reporte Diario'!$M:$M,Resumen!$B$10) -> 0 | H12: =COUNTIFS('Reporte Diario'!$K:$K,Resumen!H$9,'Reporte Diario'!$L:$L,Resumen!$B12,'Reporte Diario'!$M:$M,Resumen!$B$10) -> 0 | I12: =COUNTIFS('Reporte Diario'!$K:$K,Resumen!I$9,'Reporte Diario'!$L:$L,Resumen!$B12,'Reporte Diario'!$M:$M,Resumen!$B$10) -> 0 | J12: =COUNTIFS('Reporte Diario'!$K:$K,Resumen!J$9,'Reporte Diario'!$L:$L,Resumen!$B12,'Reporte Diario'!$M:$M,Resumen!$B$10) -> 0 | ... M12: =COUNTIFS('Reporte Diario'!$K:$K,Resumen!M$9,'Reporte Diario'!$L:$L,Resumen!$B12,'Reporte Diario'!$M:$M,Resumen!$B$10) -> 0 | N12: =SUM(C12:M12) -> 0 | P12: AISLACIÓN | Q12: =COUNTIFS('Reporte Diario'!$H:$H,Resumen!Q$9,'Reporte Diario'!$L:$L,$P12,'Reporte Diario'!$M:$M,$P$10,'Reporte Diario'!$K:$K,"OBRA") -> 0 | R12: =COUNTIFS('Reporte Diario'!$H:$H,Resumen!R$9,'Reporte Diario'!$L:$L,$P12,'Reporte Diario'!$M:$M,$P$10,'Reporte Diario'!$K:$K,"OBRA") -> 0 | S12: =COUNTIFS('Reporte Diario'!$H:$H,Resumen!S$9,'Reporte Diario'!$L:$L,$P12,'Reporte Diario'!$M:$M,$P$10,'Reporte Diario'!$K:$K,"OBRA") -> 0 | T12: =COUNTIFS('Reporte Diario'!$H:$H,Resumen!T$9,'Reporte Diario'!$L:$L,$P12,'Reporte Diario'!$M:$M,$P$10,'Reporte Diario'!$K:$K,"OBRA") -> 0 | U12: =COUNTIFS('Reporte Diario'!$H:$H,Resumen!U$9,'Reporte Diario'!$L:$L,$P12,'Reporte Diario'!$M:$M,$P$10,'Reporte Diario'!$K:$K,"DESCANSO") -> 0 | V12: =COUNTIFS('Reporte Diario'!$H:$H,Resumen!V$9,'Reporte Diario'!$L:$L,$P12,'Reporte Diario'!$M:$M,$P$10,'Reporte Diario'!$K:$K,"DESCANSO") -> 0 | W12: =COUNTIFS('Reporte Diario'!$H:$H,Resumen!W$9,'Reporte Diario'!$L:$L,$P12,'Reporte Diario'!$M:$M,$P$10,'Reporte Diario'!$K:$K,"DESCANSO") -> 0 | X12: =COUNTIFS('Reporte Diario'!$H:$H,Resumen!X$9,'Reporte Diario'!$L:$L,$P12,'Reporte Diario'!$M:$M,$P$10,'Reporte Diario'!$K:$K,"DESCANSO") -> 0 | Y12: =SUM(E12:M12) -> 0 | Z12: =SUM(Q12:Y12) -> 0
B13: CAÑERIA | C13: =COUNTIFS('Reporte Diario'!$K:$K,Resumen!C$9,'Reporte Diario'!$L:$L,Resumen!$B13,'Reporte Diario'!$M:$M,Resumen!$B$10) -> 0 | D13: =COUNTIFS('Reporte Diario'!$K:$K,Resumen!D$9,'Reporte Diario'!$L:$L,Resumen!$B13,'Reporte Diario'!$M:$M,Resumen!$B$10) -> 0 | E13: =COUNTIFS('Reporte Diario'!$K:$K,Resumen!E$9,'Reporte Diario'!$L:$L,Resumen!$B13,'Reporte Diario'!$M:$M,Resumen!$B$10) -> 0 | F13: =COUNTIFS('Reporte Diario'!$K:$K,Resumen!F$9,'Reporte Diario'!$L:$L,Resumen!$B13,'Reporte Diario'!$M:$M,Resumen!$B$10) -> 0 | G13: =COUNTIFS('Reporte Diario'!$K:$K,Resumen!G$9,'Reporte Diario'!$L:$L,Resumen!$B13,'Reporte Diario'!$M:$M,Resumen!$B$10) -> 0 | H13: =COUNTIFS('Reporte Diario'!$K:$K,Resumen!H$9,'Reporte Diario'!$L:$L,Resumen!$B13,'Reporte Diario'!$M:$M,Resumen!$B$10) -> 0 | I13: =COUNTIFS('Reporte Diario'!$K:$K,Resumen!I$9,'Reporte Diario'!$L:$L,Resumen!$B13,'Reporte Diario'!$M:$M,Resumen!$B$10) -> 0 | J13: =COUNTIFS('Reporte Diario'!$K:$K,Resumen!J$9,'Reporte Diario'!$L:$L,Resumen!$B13,'Reporte Diario'!$M:$M,Resumen!$B$10) -> 0 | ... M13: =COUNTIFS('Reporte Diario'!$K:$K,Resumen!M$9,'Reporte Diario'!$L:$L,Resumen!$B13,'Reporte Diario'!$M:$M,Resumen!$B$10) -> 0 | N13: =SUM(C13:M13) -> 0 | P13: CAÑERIA | Q13: =COUNTIFS('Reporte Diario'!$H:$H,Resumen!Q$9,'Reporte Diario'!$L:$L,$P13,'Reporte Diario'!$M:$M,$P$10,'Reporte Diario'!$K:$K,"OBRA") -> 0 | R13: =COUNTIFS('Reporte Diario'!$H:$H,Resumen!R$9,'Reporte Diario'!$L:$L,$P13,'Reporte Diario'!$M:$M,$P$10,'Reporte Diario'!$K:$K,"OBRA") -> 0 | S13: =COUNTIFS('Reporte Diario'!$H:$H,Resumen!S$9,'Reporte Diario'!$L:$L,$P13,'Reporte Diario'!$M:$M,$P$10,'Reporte Diario'!$K:$K,"OBRA") -> 0 | T13: =COUNTIFS('Reporte Diario'!$H:$H,Resumen!T$9,'Reporte Diario'!$L:$L,$P13,'Reporte Diario'!$M:$M,$P$10,'Reporte Diario'!$K:$K,"OBRA") -> 0 | U13: =COUNTIFS('Reporte Diario'!$H:$H,Resumen!U$9,'Reporte Diario'!$L:$L,$P13,'Reporte Diario'!$M:$M,$P$10,'Reporte Diario'!$K:$K,"DESCANSO") -> 0 | V13: =COUNTIFS('Reporte Diario'!$H:$H,Resumen!V$9,'Reporte Diario'!$L:$L,$P13,'Reporte Diario'!$M:$M,$P$10,'Reporte Diario'!$K:$K,"DESCANSO") -> 0 | W13: =COUNTIFS('Reporte Diario'!$H:$H,Resumen!W$9,'Reporte Diario'!$L:$L,$P13,'Reporte Diario'!$M:$M,$P$10,'Reporte Diario'!$K:$K,"DESCANSO") -> 0 | X13: =COUNTIFS('Reporte Diario'!$H:$H,Resumen!X$9,'Reporte Diario'!$L:$L,$P13,'Reporte Diario'!$M:$M,$P$10,'Reporte Diario'!$K:$K,"DESCANSO") -> 0 | Y13: =SUM(E13:M13) -> 0 | Z13: =SUM(Q13:Y13) -> 0
B14: INSTRUMENTACION | C14: =COUNTIFS('Reporte Diario'!$K:$K,Resumen!C$9,'Reporte Diario'!$L:$L,Resumen!$B14,'Reporte Diario'!$M:$M,Resumen!$B$10) -> 0 | D14: =COUNTIFS('Reporte Diario'!$K:$K,Resumen!D$9,'Reporte Diario'!$L:$L,Resumen!$B14,'Reporte Diario'!$M:$M,Resumen!$B$10) -> 0 | E14: =COUNTIFS('Reporte Diario'!$K:$K,Resumen!E$9,'Reporte Diario'!$L:$L,Resumen!$B14,'Reporte Diario'!$M:$M,Resumen!$B$10) -> 0 | F14: =COUNTIFS('Reporte Diario'!$K:$K,Resumen!F$9,'Reporte Diario'!$L:$L,Resumen!$B14,'Reporte Diario'!$M:$M,Resumen!$B$10) -> 0 | G14: =COUNTIFS('Reporte Diario'!$K:$K,Resumen!G$9,'Reporte Diario'!$L:$L,Resumen!$B14,'Reporte Diario'!$M:$M,Resumen!$B$10) -> 0 | H14: =COUNTIFS('Reporte Diario'!$K:$K,Resumen!H$9,'Reporte Diario'!$L:$L,Resumen!$B14,'Reporte Diario'!$M:$M,Resumen!$B$10) -> 0 | I14: =COUNTIFS('Reporte Diario'!$K:$K,Resumen!I$9,'Reporte Diario'!$L:$L,Resumen!$B14,'Reporte Diario'!$M:$M,Resumen!$B$10) -> 0 | J14: =COUNTIFS('Reporte Diario'!$K:$K,Resumen!J$9,'Reporte Diario'!$L:$L,Resumen!$B14,'Reporte Diario'!$M:$M,Resumen!$B$10) -> 0 | ... M14: =COUNTIFS('Reporte Diario'!$K:$K,Resumen!M$9,'Reporte Diario'!$L:$L,Resumen!$B14,'Reporte Diario'!$M:$M,Resumen!$B$10) -> 0 | N14: =SUM(C14:M14) -> 0 | P14: INSTRUMENTACION | Q14: =COUNTIFS('Reporte Diario'!$H:$H,Resumen!Q$9,'Reporte Diario'!$L:$L,$P14,'Reporte Diario'!$M:$M,$P$10,'Reporte Diario'!$K:$K,"OBRA") -> 0 | R14: =COUNTIFS('Reporte Diario'!$H:$H,Resumen!R$9,'Reporte Diario'!$L:$L,$P14,'Reporte Diario'!$M:$M,$P$10,'Reporte Diario'!$K:$K,"OBRA") -> 0 | S14: =COUNTIFS('Reporte Diario'!$H:$H,Resumen!S$9,'Reporte Diario'!$L:$L,$P14,'Reporte Diario'!$M:$M,$P$10,'Reporte Diario'!$K:$K,"OBRA") -> 0 | T14: =COUNTIFS('Reporte Diario'!$H:$H,Resumen!T$9,'Reporte Diario'!$L:$L,$P14,'Reporte Diario'!$M:$M,$P$10,'Reporte Diario'!$K:$K,"OBRA") -> 0 | U14: =COUNTIFS('Reporte Diario'!$H:$H,Resumen!U$9,'Reporte Diario'!$L:$L,$P14,'Reporte Diario'!$M:$M,$P$10,'Reporte Diario'!$K:$K,"DESCANSO") -> 0 | V14: =COUNTIFS('Reporte Diario'!$H:$H,Resumen!V$9,'Reporte Diario'!$L:$L,$P14,'Reporte Diario'!$M:$M,$P$10,'Reporte Diario'!$K:$K,"DESCANSO") -> 0 | W14: =COUNTIFS('Reporte Diario'!$H:$H,Resumen!W$9,'Reporte Diario'!$L:$L,$P14,'Reporte Diario'!$M:$M,$P$10,'Reporte Diario'!$K:$K,"DESCANSO") -> 0 | X14: =COUNTIFS('Reporte Diario'!$H:$H,Resumen!X$9,'Reporte Diario'!$L:$L,$P14,'Reporte Diario'!$M:$M,$P$10,'Reporte Diario'!$K:$K,"DESCANSO") -> 0 | Y14: =SUM(E14:M14) -> 0 | Z14: =SUM(Q14:Y14) -> 0
B15: ELECTRICOS | C15: =COUNTIFS('Reporte Diario'!$K:$K,Resumen!C$9,'Reporte Diario'!$L:$L,Resumen!$B15,'Reporte Diario'!$M:$M,Resumen!$B$10) -> 0 | D15: =COUNTIFS('Reporte Diario'!$K:$K,Resumen!D$9,'Reporte Diario'!$L:$L,Resumen!$B15,'Reporte Diario'!$M:$M,Resumen!$B$10) -> 0 | E15: =COUNTIFS('Reporte Diario'!$K:$K,Resumen!E$9,'Reporte Diario'!$L:$L,Resumen!$B15,'Reporte Diario'!$M:$M,Resumen!$B$10) -> 0 | F15: =COUNTIFS('Reporte Diario'!$K:$K,Resumen!F$9,'Reporte Diario'!$L:$L,Resumen!$B15,'Reporte Diario'!$M:$M,Resumen!$B$10) -> 0 | G15: =COUNTIFS('Reporte Diario'!$K:$K,Resumen!G$9,'Reporte Diario'!$L:$L,Resumen!$B15,'Reporte Diario'!$M:$M,Resumen!$B$10) -> 0 | H15: =COUNTIFS('Reporte Diario'!$K:$K,Resumen!H$9,'Reporte Diario'!$L:$L,Resumen!$B15,'Reporte Diario'!$M:$M,Resumen!$B$10) -> 0 | I15: =COUNTIFS('Reporte Diario'!$K:$K,Resumen!I$9,'Reporte Diario'!$L:$L,Resumen!$B15,'Reporte Diario'!$M:$M,Resumen!$B$10) -> 0 | J15: =COUNTIFS('Reporte Diario'!$K:$K,Resumen!J$9,'Reporte Diario'!$L:$L,Resumen!$B15,'Reporte Diario'!$M:$M,Resumen!$B$10) -> 0 | ... M15: =COUNTIFS('Reporte Diario'!$K:$K,Resumen!M$9,'Reporte Diario'!$L:$L,Resumen!$B15,'Reporte Diario'!$M:$M,Resumen!$B$10) -> 0 | N15: =SUM(C15:M15) -> 0 | P15: ELECTRICOS | Q15: =COUNTIFS('Reporte Diario'!$H:$H,Resumen!Q$9,'Reporte Diario'!$L:$L,$P15,'Reporte Diario'!$M:$M,$P$10,'Reporte Diario'!$K:$K,"OBRA") -> 0 | R15: =COUNTIFS('Reporte Diario'!$H:$H,Resumen!R$9,'Reporte Diario'!$L:$L,$P15,'Reporte Diario'!$M:$M,$P$10,'Reporte Diario'!$K:$K,"OBRA") -> 0 | S15: =COUNTIFS('Reporte Diario'!$H:$H,Resumen!S$9,'Reporte Diario'!$L:$L,$P15,'Reporte Diario'!$M:$M,$P$10,'Reporte Diario'!$K:$K,"OBRA") -> 0 | T15: =COUNTIFS('Reporte Diario'!$H:$H,Resumen!T$9,'Reporte Diario'!$L:$L,$P15,'Reporte Diario'!$M:$M,$P$10,'Reporte Diario'!$K:$K,"OBRA") -> 0 | U15: =COUNTIFS('Reporte Diario'!$H:$H,Resumen!U$9,'Reporte Diario'!$L:$L,$P15,'Reporte Diario'!$M:$M,$P$10,'Reporte Diario'!$K:$K,"DESCANSO") -> 0 | V15: =COUNTIFS('Reporte Diario'!$H:$H,Resumen!V$9,'Reporte Diario'!$L:$L,$P15,'Reporte Diario'!$M:$M,$P$10,'Reporte Diario'!$K:$K,"DESCANSO") -> 0 | W15: =COUNTIFS('Reporte Diario'!$H:$H,Resumen!W$9,'Reporte Diario'!$L:$L,$P15,'Reporte Diario'!$M:$M,$P$10,'Reporte Diario'!$K:$K,"DESCANSO") -> 0 | X15: =COUNTIFS('Reporte Diario'!$H:$H,Resumen!X$9,'Reporte Diario'!$L:$L,$P15,'Reporte Diario'!$M:$M,$P$10,'Reporte Diario'!$K:$K,"DESCANSO") -> 0 | Y15: =SUM(E15:M15) -> 0 | Z15: =SUM(Q15:Y15) -> 0
B16: ENFIERRADURA | C16: =COUNTIFS('Reporte Diario'!$K:$K,Resumen!C$9,'Reporte Diario'!$L:$L,Resumen!$B16,'Reporte Diario'!$M:$M,Resumen!$B$10) -> 0 | D16: =COUNTIFS('Reporte Diario'!$K:$K,Resumen!D$9,'Reporte Diario'!$L:$L,Resumen!$B16,'Reporte Diario'!$M:$M,Resumen!$B$10) -> 0 | E16: =COUNTIFS('Reporte Diario'!$K:$K,Resumen!E$9,'Reporte Diario'!$L:$L,Resumen!$B16,'Reporte Diario'!$M:$M,Resumen!$B$10) -> 0 | F16: =COUNTIFS('Reporte Diario'!$K:$K,Resumen!F$9,'Reporte Diario'!$L:$L,Resumen!$B16,'Reporte Diario'!$M:$M,Resumen!$B$10) -> 0 | G16: =COUNTIFS('Reporte Diario'!$K:$K,Resumen!G$9,'Reporte Diario'!$L:$L,Resumen!$B16,'Reporte Diario'!$M:$M,Resumen!$B$10) -> 0 | H16: =COUNTIFS('Reporte Diario'!$K:$K,Resumen!H$9,'Reporte Diario'!$L:$L,Resumen!$B16,'Reporte Diario'!$M:$M,Resumen!$B$10) -> 0 | I16: =COUNTIFS('Reporte Diario'!$K:$K,Resumen!I$9,'Reporte Diario'!$L:$L,Resumen!$B16,'Reporte Diario'!$M:$M,Resumen!$B$10) -> 0 | J16: =COUNTIFS('Reporte Diario'!$K:$K,Resumen!J$9,'Reporte Diario'!$L:$L,Resumen!$B16,'Reporte Diario'!$M:$M,Resumen!$B$10) -> 0 | ... M16: =COUNTIFS('Reporte Diario'!$K:$K,Resumen!M$9,'Reporte Diario'!$L:$L,Resumen!$B16,'Reporte Diario'!$M:$M,Resumen!$B$10) -> 0 | N16: =SUM(C16:M16) -> 0 | P16: ENFIERRADURA | Q16: =COUNTIFS('Reporte Diario'!$H:$H,Resumen!Q$9,'Reporte Diario'!$L:$L,$P16,'Reporte Diario'!$M:$M,$P$10,'Reporte Diario'!$K:$K,"OBRA") -> 0 | R16: =COUNTIFS('Reporte Diario'!$H:$H,Resumen!R$9,'Reporte Diario'!$L:$L,$P16,'Reporte Diario'!$M:$M,$P$10,'Reporte Diario'!$K:$K,"OBRA") -> 0 | S16: =COUNTIFS('Reporte Diario'!$H:$H,Resumen!S$9,'Reporte Diario'!$L:$L,$P16,'Reporte Diario'!$M:$M,$P$10,'Reporte Diario'!$K:$K,"OBRA") -> 0 | T16: =COUNTIFS('Reporte Diario'!$H:$H,Resumen!T$9,'Reporte Diario'!$L:$L,$P16,'Reporte Diario'!$M:$M,$P$10,'Reporte Diario'!$K:$K,"OBRA") -> 0 | U16: =COUNTIFS('Reporte Diario'!$H:$H,Resumen!U$9,'Reporte Diario'!$L:$L,$P16,'Reporte Diario'!$M:$M,$P$10,'Reporte Diario'!$K:$K,"DESCANSO") -> 0 | V16: =COUNTIFS('Reporte Diario'!$H:$H,Resumen!V$9,'Reporte Diario'!$L:$L,$P16,'Reporte Diario'!$M:$M,$P$10,'Reporte Diario'!$K:$K,"DESCANSO") -> 0 | W16: =COUNTIFS('Reporte Diario'!$H:$H,Resumen!W$9,'Reporte Diario'!$L:$L,$P16,'Reporte Diario'!$M:$M,$P$10,'Reporte Diario'!$K:$K,"DESCANSO") -> 0 | X16: =COUNTIFS('Reporte Diario'!$H:$H,Resumen!X$9,'Reporte Diario'!$L:$L,$P16,'Reporte Diario'!$M:$M,$P$10,'Reporte Diario'!$K:$K,"DESCANSO") -> 0 | Y16: =SUM(E16:M16) -> 0 | Z16: =SUM(Q16:Y16) -> 0
B17: ESTRUCTURA | C17: =COUNTIFS('Reporte Diario'!$K:$K,Resumen!C$9,'Reporte Diario'!$L:$L,Resumen!$B17,'Reporte Diario'!$M:$M,Resumen!$B$10) -> 0 | D17: =COUNTIFS('Reporte Diario'!$K:$K,Resumen!D$9,'Reporte Diario'!$L:$L,Resumen!$B17,'Reporte Diario'!$M:$M,Resumen!$B$10) -> 0 | E17: =COUNTIFS('Reporte Diario'!$K:$K,Resumen!E$9,'Reporte Diario'!$L:$L,Resumen!$B17,'Reporte Diario'!$M:$M,Resumen!$B$10) -> 0 | F17: =COUNTIFS('Reporte Diario'!$K:$K,Resumen!F$9,'Reporte Diario'!$L:$L,Resumen!$B17,'Reporte Diario'!$M:$M,Resumen!$B$10) -> 0 | G17: =COUNTIFS('Reporte Diario'!$K:$K,Resumen!G$9,'Reporte Diario'!$L:$L,Resumen!$B17,'Reporte Diario'!$M:$M,Resumen!$B$10) -> 0 | H17: =COUNTIFS('Reporte Diario'!$K:$K,Resumen!H$9,'Reporte Diario'!$L:$L,Resumen!$B17,'Reporte Diario'!$M:$M,Resumen!$B$10) -> 0 | I17: =COUNTIFS('Reporte Diario'!$K:$K,Resumen!I$9,'Reporte Diario'!$L:$L,Resumen!$B17,'Reporte Diario'!$M:$M,Resumen!$B$10) -> 0 | J17: =COUNTIFS('Reporte Diario'!$K:$K,Resumen!J$9,'Reporte Diario'!$L:$L,Resumen!$B17,'Reporte Diario'!$M:$M,Resumen!$B$10) -> 0 | ... M17: =COUNTIFS('Reporte Diario'!$K:$K,Resumen!M$9,'Reporte Diario'!$L:$L,Resumen!$B17,'Reporte Diario'!$M:$M,Resumen!$B$10) -> 0 | N17: =SUM(C17:M17) -> 0 | P17: ESTRUCTURA | Q17: =COUNTIFS('Reporte Diario'!$H:$H,Resumen!Q$9,'Reporte Diario'!$L:$L,$P17,'Reporte Diario'!$M:$M,$P$10,'Reporte Diario'!$K:$K,"OBRA") -> 0 | R17: =COUNTIFS('Reporte Diario'!$H:$H,Resumen!R$9,'Reporte Diario'!$L:$L,$P17,'Reporte Diario'!$M:$M,$P$10,'Reporte Diario'!$K:$K,"OBRA") -> 0 | S17: =COUNTIFS('Reporte Diario'!$H:$H,Resumen!S$9,'Reporte Diario'!$L:$L,$P17,'Reporte Diario'!$M:$M,$P$10,'Reporte Diario'!$K:$K,"OBRA") -> 0 | T17: =COUNTIFS('Reporte Diario'!$H:$H,Resumen!T$9,'Reporte Diario'!$L:$L,$P17,'Reporte Diario'!$M:$M,$P$10,'Reporte Diario'!$K:$K,"OBRA") -> 0 | U17: =COUNTIFS('Reporte Diario'!$H:$H,Resumen!U$9,'Reporte Diario'!$L:$L,$P17,'Reporte Diario'!$M:$M,$P$10,'Reporte Diario'!$K:$K,"DESCANSO") -> 0 | V17: =COUNTIFS('Reporte Diario'!$H:$H,Resumen!V$9,'Reporte Diario'!$L:$L,$P17,'Reporte Diario'!$M:$M,$P$10,'Reporte Diario'!$K:$K,"DESCANSO") -> 0 | W17: =COUNTIFS('Reporte Diario'!$H:$H,Resumen!W$9,'Reporte Diario'!$L:$L,$P17,'Reporte Diario'!$M:$M,$P$10,'Reporte Diario'!$K:$K,"DESCANSO") -> 0 | X17: =COUNTIFS('Reporte Diario'!$H:$H,Resumen!X$9,'Reporte Diario'!$L:$L,$P17,'Reporte Diario'!$M:$M,$P$10,'Reporte Diario'!$K:$K,"DESCANSO") -> 0 | Y17: =SUM(E17:M17) -> 0 | Z17: =SUM(Q17:Y17) -> 0
B18: MECANICA | C18: =COUNTIFS('Reporte Diario'!$K:$K,Resumen!C$9,'Reporte Diario'!$L:$L,Resumen!$B18,'Reporte Diario'!$M:$M,Resumen!$B$10) -> 0 | D18: =COUNTIFS('Reporte Diario'!$K:$K,Resumen!D$9,'Reporte Diario'!$L:$L,Resumen!$B18,'Reporte Diario'!$M:$M,Resumen!$B$10) -> 0 | E18: =COUNTIFS('Reporte Diario'!$K:$K,Resumen!E$9,'Reporte Diario'!$L:$L,Resumen!$B18,'Reporte Diario'!$M:$M,Resumen!$B$10) -> 0 | F18: =COUNTIFS('Reporte Diario'!$K:$K,Resumen!F$9,'Reporte Diario'!$L:$L,Resumen!$B18,'Reporte Diario'!$M:$M,Resumen!$B$10) -> 0 | G18: =COUNTIFS('Reporte Diario'!$K:$K,Resumen!G$9,'Reporte Diario'!$L:$L,Resumen!$B18,'Reporte Diario'!$M:$M,Resumen!$B$10) -> 0 | H18: =COUNTIFS('Reporte Diario'!$K:$K,Resumen!H$9,'Reporte Diario'!$L:$L,Resumen!$B18,'Reporte Diario'!$M:$M,Resumen!$B$10) -> 0 | I18: =COUNTIFS('Reporte Diario'!$K:$K,Resumen!I$9,'Reporte Diario'!$L:$L,Resumen!$B18,'Reporte Diario'!$M:$M,Resumen!$B$10) -> 0 | J18: =COUNTIFS('Reporte Diario'!$K:$K,Resumen!J$9,'Reporte Diario'!$L:$L,Resumen!$B18,'Reporte Diario'!$M:$M,Resumen!$B$10) -> 0 | ... M18: =COUNTIFS('Reporte Diario'!$K:$K,Resumen!M$9,'Reporte Diario'!$L:$L,Resumen!$B18,'Reporte Diario'!$M:$M,Resumen!$B$10) -> 0 | N18: =SUM(C18:M18) -> 0 | P18: MECANICA | Q18: =COUNTIFS('Reporte Diario'!$H:$H,Resumen!Q$9,'Reporte Diario'!$L:$L,$P18,'Reporte Diario'!$M:$M,$P$10,'Reporte Diario'!$K:$K,"OBRA") -> 0 | R18: =COUNTIFS('Reporte Diario'!$H:$H,Resumen!R$9,'Reporte Diario'!$L:$L,$P18,'Reporte Diario'!$M:$M,$P$10,'Reporte Diario'!$K:$K,"OBRA") -> 0 | S18: =COUNTIFS('Reporte Diario'!$H:$H,Resumen!S$9,'Reporte Diario'!$L:$L,$P18,'Reporte Diario'!$M:$M,$P$10,'Reporte Diario'!$K:$K,"OBRA") -> 0 | T18: =COUNTIFS('Reporte Diario'!$H:$H,Resumen!T$9,'Reporte Diario'!$L:$L,$P18,'Reporte Diario'!$M:$M,$P$10,'Reporte Diario'!$K:$K,"OBRA") -> 0 | U18: =COUNTIFS('Reporte Diario'!$H:$H,Resumen!U$9,'Reporte Diario'!$L:$L,$P18,'Reporte Diario'!$M:$M,$P$10,'Reporte Diario'!$K:$K,"DESCANSO") -> 0 | V18: =COUNTIFS('Reporte Diario'!$H:$H,Resumen!V$9,'Reporte Diario'!$L:$L,$P18,'Reporte Diario'!$M:$M,$P$10,'Reporte Diario'!$K:$K,"DESCANSO") -> 0 | W18: =COUNTIFS('Reporte Diario'!$H:$H,Resumen!W$9,'Reporte Diario'!$L:$L,$P18,'Reporte Diario'!$M:$M,$P$10,'Reporte Diario'!$K:$K,"DESCANSO") -> 0 | X18: =COUNTIFS('Reporte Diario'!$H:$H,Resumen!X$9,'Reporte Diario'!$L:$L,$P18,'Reporte Diario'!$M:$M,$P$10,'Reporte Diario'!$K:$K,"DESCANSO") -> 0 | Y18: =SUM(E18:M18) -> 0 | Z18: =SUM(Q18:Y18) -> 0
B19: PINTURA | C19: =COUNTIFS('Reporte Diario'!$K:$K,Resumen!C$9,'Reporte Diario'!$L:$L,Resumen!$B19,'Reporte Diario'!$M:$M,Resumen!$B$10) -> 0 | D19: =COUNTIFS('Reporte Diario'!$K:$K,Resumen!D$9,'Reporte Diario'!$L:$L,Resumen!$B19,'Reporte Diario'!$M:$M,Resumen!$B$10) -> 0 | E19: =COUNTIFS('Reporte Diario'!$K:$K,Resumen!E$9,'Reporte Diario'!$L:$L,Resumen!$B19,'Reporte Diario'!$M:$M,Resumen!$B$10) -> 0 | F19: =COUNTIFS('Reporte Diario'!$K:$K,Resumen!F$9,'Reporte Diario'!$L:$L,Resumen!$B19,'Reporte Diario'!$M:$M,Resumen!$B$10) -> 0 | G19: =COUNTIFS('Reporte Diario'!$K:$K,Resumen!G$9,'Reporte Diario'!$L:$L,Resumen!$B19,'Reporte Diario'!$M:$M,Resumen!$B$10) -> 0 | H19: =COUNTIFS('Reporte Diario'!$K:$K,Resumen!H$9,'Reporte Diario'!$L:$L,Resumen!$B19,'Reporte Diario'!$M:$M,Resumen!$B$10) -> 0 | I19: =COUNTIFS('Reporte Diario'!$K:$K,Resumen!I$9,'Reporte Diario'!$L:$L,Resumen!$B19,'Reporte Diario'!$M:$M,Resumen!$B$10) -> 0 | J19: =COUNTIFS('Reporte Diario'!$K:$K,Resumen!J$9,'Reporte Diario'!$L:$L,Resumen!$B19,'Reporte Diario'!$M:$M,Resumen!$B$10) -> 0 | ... M19: =COUNTIFS('Reporte Diario'!$K:$K,Resumen!M$9,'Reporte Diario'!$L:$L,Resumen!$B19,'Reporte Diario'!$M:$M,Resumen!$B$10) -> 0 | N19: =SUM(C19:M19) -> 0 | P19: PINTURA | Q19: =COUNTIFS('Reporte Diario'!$H:$H,Resumen!Q$9,'Reporte Diario'!$L:$L,$P19,'Reporte Diario'!$M:$M,$P$10,'Reporte Diario'!$K:$K,"OBRA") -> 0 | R19: =COUNTIFS('Reporte Diario'!$H:$H,Resumen!R$9,'Reporte Diario'!$L:$L,$P19,'Reporte Diario'!$M:$M,$P$10,'Reporte Diario'!$K:$K,"OBRA") -> 0 | S19: =COUNTIFS('Reporte Diario'!$H:$H,Resumen!S$9,'Reporte Diario'!$L:$L,$P19,'Reporte Diario'!$M:$M,$P$10,'Reporte Diario'!$K:$K,"OBRA") -> 0 | T19: =COUNTIFS('Reporte Diario'!$H:$H,Resumen!T$9,'Reporte Diario'!$L:$L,$P19,'Reporte Diario'!$M:$M,$P$10,'Reporte Diario'!$K:$K,"OBRA") -> 0 | U19: =COUNTIFS('Reporte Diario'!$H:$H,Resumen!U$9,'Reporte Diario'!$L:$L,$P19,'Reporte Diario'!$M:$M,$P$10,'Reporte Diario'!$K:$K,"DESCANSO") -> 0 | V19: =COUNTIFS('Reporte Diario'!$H:$H,Resumen!V$9,'Reporte Diario'!$L:$L,$P19,'Reporte Diario'!$M:$M,$P$10,'Reporte Diario'!$K:$K,"DESCANSO") -> 0 | W19: =COUNTIFS('Reporte Diario'!$H:$H,Resumen!W$9,'Reporte Diario'!$L:$L,$P19,'Reporte Diario'!$M:$M,$P$10,'Reporte Diario'!$K:$K,"DESCANSO") -> 0 | X19: =COUNTIFS('Reporte Diario'!$H:$H,Resumen!X$9,'Reporte Diario'!$L:$L,$P19,'Reporte Diario'!$M:$M,$P$10,'Reporte Diario'!$K:$K,"DESCANSO") -> 0 | Y19: =SUM(E19:M19) -> 0 | Z19: =SUM(Q19:Y19) -> 0
B20: OBRAS CIVILES | C20: =COUNTIFS('Reporte Diario'!$K:$K,Resumen!C$9,'Reporte Diario'!$L:$L,Resumen!$B20,'Reporte Diario'!$M:$M,Resumen!$B$10) -> 0 | D20: =COUNTIFS('Reporte Diario'!$K:$K,Resumen!D$9,'Reporte Diario'!$L:$L,Resumen!$B20,'Reporte Diario'!$M:$M,Resumen!$B$10) -> 0 | E20: =COUNTIFS('Reporte Diario'!$K:$K,Resumen!E$9,'Reporte Diario'!$L:$L,Resumen!$B20,'Reporte Diario'!$M:$M,Resumen!$B$10) -> 0 | F20: =COUNTIFS('Reporte Diario'!$K:$K,Resumen!F$9,'Reporte Diario'!$L:$L,Resumen!$B20,'Reporte Diario'!$M:$M,Resumen!$B$10) -> 0 | G20: =COUNTIFS('Reporte Diario'!$K:$K,Resumen!G$9,'Reporte Diario'!$L:$L,Resumen!$B20,'Reporte Diario'!$M:$M,Resumen!$B$10) -> 0 | H20: =COUNTIFS('Reporte Diario'!$K:$K,Resumen!H$9,'Reporte Diario'!$L:$L,Resumen!$B20,'Reporte Diario'!$M:$M,Resumen!$B$10) -> 0 | I20: =COUNTIFS('Reporte Diario'!$K:$K,Resumen!I$9,'Reporte Diario'!$L:$L,Resumen!$B20,'Reporte Diario'!$M:$M,Resumen!$B$10) -> 0 | J20: =COUNTIFS('Reporte Diario'!$K:$K,Resumen!J$9,'Reporte Diario'!$L:$L,Resumen!$B20,'Reporte Diario'!$M:$M,Resumen!$B$10) -> 0 | ... M20: =COUNTIFS('Reporte Diario'!$K:$K,Resumen!M$9,'Reporte Diario'!$L:$L,Resumen!$B20,'Reporte Diario'!$M:$M,Resumen!$B$10) -> 0 | N20: =SUM(C20:M20) -> 0 | P20: OBRAS CIVILES | Q20: =COUNTIFS('Reporte Diario'!$H:$H,Resumen!Q$9,'Reporte Diario'!$L:$L,$P20,'Reporte Diario'!$M:$M,$P$10,'Reporte Diario'!$K:$K,"OBRA") -> 0 | R20: =COUNTIFS('Reporte Diario'!$H:$H,Resumen!R$9,'Reporte Diario'!$L:$L,$P20,'Reporte Diario'!$M:$M,$P$10,'Reporte Diario'!$K:$K,"OBRA") -> 0 | S20: =COUNTIFS('Reporte Diario'!$H:$H,Resumen!S$9,'Reporte Diario'!$L:$L,$P20,'Reporte Diario'!$M:$M,$P$10,'Reporte Diario'!$K:$K,"OBRA") -> 0 | T20: =COUNTIFS('Reporte Diario'!$H:$H,Resumen!T$9,'Reporte Diario'!$L:$L,$P20,'Reporte Diario'!$M:$M,$P$10,'Reporte Diario'!$K:$K,"OBRA") -> 0 | U20: =COUNTIFS('Reporte Diario'!$H:$H,Resumen!U$9,'Reporte Diario'!$L:$L,$P20,'Reporte Diario'!$M:$M,$P$10,'Reporte Diario'!$K:$K,"DESCANSO") -> 0 | V20: =COUNTIFS('Reporte Diario'!$H:$H,Resumen!V$9,'Reporte Diario'!$L:$L,$P20,'Reporte Diario'!$M:$M,$P$10,'Reporte Diario'!$K:$K,"DESCANSO") -> 0 | W20: =COUNTIFS('Reporte Diario'!$H:$H,Resumen!W$9,'Reporte Diario'!$L:$L,$P20,'Reporte Diario'!$M:$M,$P$10,'Reporte Diario'!$K:$K,"DESCANSO") -> 0 | X20: =COUNTIFS('Reporte Diario'!$H:$H,Resumen!X$9,'Reporte Diario'!$L:$L,$P20,'Reporte Diario'!$M:$M,$P$10,'Reporte Diario'!$K:$K,"DESCANSO") -> 0 | Y20: =SUM(E20:M20) -> 0 | Z20: =SUM(Q20:Y20) -> 0
B21: SOLDADURA | C21: =COUNTIFS('Reporte Diario'!$K:$K,Resumen!C$9,'Reporte Diario'!$L:$L,Resumen!$B21,'Reporte Diario'!$M:$M,Resumen!$B$10) -> 0 | D21: =COUNTIFS('Reporte Diario'!$K:$K,Resumen!D$9,'Reporte Diario'!$L:$L,Resumen!$B21,'Reporte Diario'!$M:$M,Resumen!$B$10) -> 0 | E21: =COUNTIFS('Reporte Diario'!$K:$K,Resumen!E$9,'Reporte Diario'!$L:$L,Resumen!$B21,'Reporte Diario'!$M:$M,Resumen!$B$10) -> 0 | F21: =COUNTIFS('Reporte Diario'!$K:$K,Resumen!F$9,'Reporte Diario'!$L:$L,Resumen!$B21,'Reporte Diario'!$M:$M,Resumen!$B$10) -> 0 | G21: =COUNTIFS('Reporte Diario'!$K:$K,Resumen!G$9,'Reporte Diario'!$L:$L,Resumen!$B21,'Reporte Diario'!$M:$M,Resumen!$B$10) -> 0 | H21: =COUNTIFS('Reporte Diario'!$K:$K,Resumen!H$9,'Reporte Diario'!$L:$L,Resumen!$B21,'Reporte Diario'!$M:$M,Resumen!$B$10) -> 0 | I21: =COUNTIFS('Reporte Diario'!$K:$K,Resumen!I$9,'Reporte Diario'!$L:$L,Resumen!$B21,'Reporte Diario'!$M:$M,Resumen!$B$10) -> 0 | J21: =COUNTIFS('Reporte Diario'!$K:$K,Resumen!J$9,'Reporte Diario'!$L:$L,Resumen!$B21,'Reporte Diario'!$M:$M,Resumen!$B$10) -> 0 | ... M21: =COUNTIFS('Reporte Diario'!$K:$K,Resumen!M$9,'Reporte Diario'!$L:$L,Resumen!$B21,'Reporte Diario'!$M:$M,Resumen!$B$10) -> 0 | N21: =SUM(C21:M21) -> 0 | P21: SOLDADURA | Q21: =COUNTIFS('Reporte Diario'!$H:$H,Resumen!Q$9,'Reporte Diario'!$L:$L,$P21,'Reporte Diario'!$M:$M,$P$10,'Reporte Diario'!$K:$K,"OBRA") -> 0 | R21: =COUNTIFS('Reporte Diario'!$H:$H,Resumen!R$9,'Reporte Diario'!$L:$L,$P21,'Reporte Diario'!$M:$M,$P$10,'Reporte Diario'!$K:$K,"OBRA") -> 0 | S21: =COUNTIFS('Reporte Diario'!$H:$H,Resumen!S$9,'Reporte Diario'!$L:$L,$P21,'Reporte Diario'!$M:$M,$P$10,'Reporte Diario'!$K:$K,"OBRA") -> 0 | T21: =COUNTIFS('Reporte Diario'!$H:$H,Resumen!T$9,'Reporte Diario'!$L:$L,$P21,'Reporte Diario'!$M:$M,$P$10,'Reporte Diario'!$K:$K,"OBRA") -> 0 | U21: =COUNTIFS('Reporte Diario'!$H:$H,Resumen!U$9,'Reporte Diario'!$L:$L,$P21,'Reporte Diario'!$M:$M,$P$10,'Reporte Diario'!$K:$K,"DESCANSO") -> 0 | V21: =COUNTIFS('Reporte Diario'!$H:$H,Resumen!V$9,'Reporte Diario'!$L:$L,$P21,'Reporte Diario'!$M:$M,$P$10,'Reporte Diario'!$K:$K,"DESCANSO") -> 0 | W21: =COUNTIFS('Reporte Diario'!$H:$H,Resumen!W$9,'Reporte Diario'!$L:$L,$P21,'Reporte Diario'!$M:$M,$P$10,'Reporte Diario'!$K:$K,"DESCANSO") -> 0 | X21: =COUNTIFS('Reporte Diario'!$H:$H,Resumen!X$9,'Reporte Diario'!$L:$L,$P21,'Reporte Diario'!$M:$M,$P$10,'Reporte Diario'!$K:$K,"DESCANSO") -> 0 | Y21: =SUM(E21:M21) -> 0 | Z21: =SUM(Q21:Y21) -> 0
B23: ASISTENCIA | C23: OBRA | D23: DESCANSO | E23: LICENCIA MEDICA | F23: PERMISO C/GOCE | G23: PERMISO S/GOCE | H23: FALLA | I23: VACACIONES | J23: TELETRABAJO | K23: OFICINA SANTIAGO | L23: EN TRANSITO | M23: ACREDITADO | N23: TOTAL GENERAL | P23: TURNOS | Q23: 05x02 | R23: 08x06 | S23: 14x14 | T23: 15x13 | U23: 05x02 | V23: 08x06 | W23: 14x14 | X23: 15x13 | Y23: OTROS | Z23: TOTAL GENERAL
B24: MOI | C24: =SUM(C25:C39) -> 0 | D24: =SUM(D25:D39) -> 0 | E24: =SUM(E25:E39) -> 0 | F24: =SUM(F25:F39) -> 0 | G24: =SUM(G25:G39) -> 0 | H24: =SUM(H25:H39) -> 0 | I24: =SUM(I25:I39) -> 0 | J24: =SUM(J25:J39) -> 0 | ... M24: =SUM(M25:M39) -> 0 | N24: =SUM(C24:L24) -> 0 | P24: MOI | Q24: =SUM(Q25:Q39) -> 0 | R24: =SUM(R25:R39) -> 0 | S24: =SUM(S25:S39) -> 0 | T24: =SUM(T25:T39) -> 0 | U24: =SUM(U25:U39) -> 0 | V24: =SUM(V25:V39) -> 0 | W24: =SUM(W25:W39) -> 0 | X24: =SUM(X25:X39) -> 0 | Y24: =SUM(Y25:Y39) -> 0 | Z24: =SUM(Q24:Y24) -> 0
B25: ADMINISTRACION | C25: =COUNTIFS('Reporte Diario'!$K:$K,Resumen!C$9,'Reporte Diario'!$L:$L,Resumen!$B25,'Reporte Diario'!$M:$M,$B$24) -> 0 | D25: =COUNTIFS('Reporte Diario'!$K:$K,Resumen!D$9,'Reporte Diario'!$L:$L,Resumen!$B25,'Reporte Diario'!$M:$M,$B$24) -> 0 | E25: =COUNTIFS('Reporte Diario'!$K:$K,Resumen!E$9,'Reporte Diario'!$L:$L,Resumen!$B25,'Reporte Diario'!$M:$M,$B$24) -> 0 | F25: =COUNTIFS('Reporte Diario'!$K:$K,Resumen!F$9,'Reporte Diario'!$L:$L,Resumen!$B25,'Reporte Diario'!$M:$M,$B$24) -> 0 | G25: =COUNTIFS('Reporte Diario'!$K:$K,Resumen!G$9,'Reporte Diario'!$L:$L,Resumen!$B25,'Reporte Diario'!$M:$M,$B$24) -> 0 | H25: =COUNTIFS('Reporte Diario'!$K:$K,Resumen!H$9,'Reporte Diario'!$L:$L,Resumen!$B25,'Reporte Diario'!$M:$M,$B$24) -> 0 | I25: =COUNTIFS('Reporte Diario'!$K:$K,Resumen!I$9,'Reporte Diario'!$L:$L,Resumen!$B25,'Reporte Diario'!$M:$M,$B$24) -> 0 | J25: =COUNTIFS('Reporte Diario'!$K:$K,Resumen!J$9,'Reporte Diario'!$L:$L,Resumen!$B25,'Reporte Diario'!$M:$M,$B$24) -> 0 | ... M25: =COUNTIFS('Reporte Diario'!$K:$K,Resumen!M$9,'Reporte Diario'!$L:$L,Resumen!$B25,'Reporte Diario'!$M:$M,$B$24) -> 0 | N25: =SUM(C25:L25) -> 0 | P25: ADMINISTRACION | Q25: =COUNTIFS('Reporte Diario'!$H:$H,Resumen!Q$23,'Reporte Diario'!$L:$L,$P25,'Reporte Diario'!$M:$M,$P$24,'Reporte Diario'!$K:$K,"OBRA") -> 0 | R25: =COUNTIFS('Reporte Diario'!$H:$H,Resumen!R$23,'Reporte Diario'!$L:$L,$P25,'Reporte Diario'!$M:$M,$P$24,'Reporte Diario'!$K:$K,"OBRA") -> 0 | S25: =COUNTIFS('Reporte Diario'!$H:$H,Resumen!S$23,'Reporte Diario'!$L:$L,$P25,'Reporte Diario'!$M:$M,$P$24,'Reporte Diario'!$K:$K,"OBRA") -> 0 | T25: =COUNTIFS('Reporte Diario'!$H:$H,Resumen!T$23,'Reporte Diario'!$L:$L,$P25,'Reporte Diario'!$M:$M,$P$24,'Reporte Diario'!$K:$K,"OBRA") -> 0 | U25: =COUNTIFS('Reporte Diario'!$H:$H,Resumen!U$23,'Reporte Diario'!$L:$L,$P25,'Reporte Diario'!$M:$M,$P$24,'Reporte Diario'!$K:$K,"DESCANSO") -> 0 | V25: =COUNTIFS('Reporte Diario'!$H:$H,Resumen!V$23,'Reporte Diario'!$L:$L,$P25,'Reporte Diario'!$M:$M,$P$24,'Reporte Diario'!$K:$K,"DESCANSO") -> 0 | W25: =COUNTIFS('Reporte Diario'!$H:$H,Resumen!W$23,'Reporte Diario'!$L:$L,$P25,'Reporte Diario'!$M:$M,$P$24,'Reporte Diario'!$K:$K,"DESCANSO") -> 0 | X25: =COUNTIFS('Reporte Diario'!$H:$H,Resumen!X$23,'Reporte Diario'!$L:$L,$P25,'Reporte Diario'!$M:$M,$P$24,'Reporte Diario'!$K:$K,"DESCANSO") -> 0 | Y25: =SUM(E25:M25) -> 0 | Z25: =SUM(Q25:Y25) -> 0
B26: BODEGA | C26: =COUNTIFS('Reporte Diario'!$K:$K,Resumen!C$9,'Reporte Diario'!$L:$L,Resumen!$B26,'Reporte Diario'!$M:$M,$B$24) -> 0 | D26: =COUNTIFS('Reporte Diario'!$K:$K,Resumen!D$9,'Reporte Diario'!$L:$L,Resumen!$B26,'Reporte Diario'!$M:$M,$B$24) -> 0 | E26: =COUNTIFS('Reporte Diario'!$K:$K,Resumen!E$9,'Reporte Diario'!$L:$L,Resumen!$B26,'Reporte Diario'!$M:$M,$B$24) -> 0 | F26: =COUNTIFS('Reporte Diario'!$K:$K,Resumen!F$9,'Reporte Diario'!$L:$L,Resumen!$B26,'Reporte Diario'!$M:$M,$B$24) -> 0 | G26: =COUNTIFS('Reporte Diario'!$K:$K,Resumen!G$9,'Reporte Diario'!$L:$L,Resumen!$B26,'Reporte Diario'!$M:$M,$B$24) -> 0 | H26: =COUNTIFS('Reporte Diario'!$K:$K,Resumen!H$9,'Reporte Diario'!$L:$L,Resumen!$B26,'Reporte Diario'!$M:$M,$B$24) -> 0 | I26: =COUNTIFS('Reporte Diario'!$K:$K,Resumen!I$9,'Reporte Diario'!$L:$L,Resumen!$B26,'Reporte Diario'!$M:$M,$B$24) -> 0 | J26: =COUNTIFS('Reporte Diario'!$K:$K,Resumen!J$9,'Reporte Diario'!$L:$L,Resumen!$B26,'Reporte Diario'!$M:$M,$B$24) -> 0 | ... M26: =COUNTIFS('Reporte Diario'!$K:$K,Resumen!M$9,'Reporte Diario'!$L:$L,Resumen!$B26,'Reporte Diario'!$M:$M,$B$24) -> 0 | N26: =SUM(C26:L26) -> 0 | P26: BODEGA | Q26: =COUNTIFS('Reporte Diario'!$H:$H,Resumen!Q$23,'Reporte Diario'!$L:$L,$P26,'Reporte Diario'!$M:$M,$P$24,'Reporte Diario'!$K:$K,"OBRA") -> 0 | R26: =COUNTIFS('Reporte Diario'!$H:$H,Resumen!R$23,'Reporte Diario'!$L:$L,$P26,'Reporte Diario'!$M:$M,$P$24,'Reporte Diario'!$K:$K,"OBRA") -> 0 | S26: =COUNTIFS('Reporte Diario'!$H:$H,Resumen!S$23,'Reporte Diario'!$L:$L,$P26,'Reporte Diario'!$M:$M,$P$24,'Reporte Diario'!$K:$K,"OBRA") -> 0 | T26: =COUNTIFS('Reporte Diario'!$H:$H,Resumen!T$23,'Reporte Diario'!$L:$L,$P26,'Reporte Diario'!$M:$M,$P$24,'Reporte Diario'!$K:$K,"OBRA") -> 0 | U26: =COUNTIFS('Reporte Diario'!$H:$H,Resumen!U$23,'Reporte Diario'!$L:$L,$P26,'Reporte Diario'!$M:$M,$P$24,'Reporte Diario'!$K:$K,"DESCANSO") -> 0 | V26: =COUNTIFS('Reporte Diario'!$H:$H,Resumen!V$23,'Reporte Diario'!$L:$L,$P26,'Reporte Diario'!$M:$M,$P$24,'Reporte Diario'!$K:$K,"DESCANSO") -> 0 | W26: =COUNTIFS('Reporte Diario'!$H:$H,Resumen!W$23,'Reporte Diario'!$L:$L,$P26,'Reporte Diario'!$M:$M,$P$24,'Reporte Diario'!$K:$K,"DESCANSO") -> 0 | X26: =COUNTIFS('Reporte Diario'!$H:$H,Resumen!X$23,'Reporte Diario'!$L:$L,$P26,'Reporte Diario'!$M:$M,$P$24,'Reporte Diario'!$K:$K,"DESCANSO") -> 0 | Y26: =SUM(E26:M26) -> 0 | Z26: =SUM(Q26:Y26) -> 0
B27: ELECTRICOS MANTENCION | C27: =COUNTIFS('Reporte Diario'!$K:$K,Resumen!C$9,'Reporte Diario'!$L:$L,Resumen!$B27,'Reporte Diario'!$M:$M,$B$24) -> 0 | D27: =COUNTIFS('Reporte Diario'!$K:$K,Resumen!D$9,'Reporte Diario'!$L:$L,Resumen!$B27,'Reporte Diario'!$M:$M,$B$24) -> 0 | E27: =COUNTIFS('Reporte Diario'!$K:$K,Resumen!E$9,'Reporte Diario'!$L:$L,Resumen!$B27,'Reporte Diario'!$M:$M,$B$24) -> 0 | F27: =COUNTIFS('Reporte Diario'!$K:$K,Resumen!F$9,'Reporte Diario'!$L:$L,Resumen!$B27,'Reporte Diario'!$M:$M,$B$24) -> 0 | G27: =COUNTIFS('Reporte Diario'!$K:$K,Resumen!G$9,'Reporte Diario'!$L:$L,Resumen!$B27,'Reporte Diario'!$M:$M,$B$24) -> 0 | H27: =COUNTIFS('Reporte Diario'!$K:$K,Resumen!H$9,'Reporte Diario'!$L:$L,Resumen!$B27,'Reporte Diario'!$M:$M,$B$24) -> 0 | I27: =COUNTIFS('Reporte Diario'!$K:$K,Resumen!I$9,'Reporte Diario'!$L:$L,Resumen!$B27,'Reporte Diario'!$M:$M,$B$24) -> 0 | J27: =COUNTIFS('Reporte Diario'!$K:$K,Resumen!J$9,'Reporte Diario'!$L:$L,Resumen!$B27,'Reporte Diario'!$M:$M,$B$24) -> 0 | ... M27: =COUNTIFS('Reporte Diario'!$K:$K,Resumen!M$9,'Reporte Diario'!$L:$L,Resumen!$B27,'Reporte Diario'!$M:$M,$B$24) -> 0 | N27: =SUM(C27:L27) -> 0 | P27: ELECTRICOS MANTENCION | Q27: =COUNTIFS('Reporte Diario'!$H:$H,Resumen!Q$23,'Reporte Diario'!$L:$L,$P27,'Reporte Diario'!$M:$M,$P$24,'Reporte Diario'!$K:$K,"OBRA") -> 0 | R27: =COUNTIFS('Reporte Diario'!$H:$H,Resumen!R$23,'Reporte Diario'!$L:$L,$P27,'Reporte Diario'!$M:$M,$P$24,'Reporte Diario'!$K:$K,"OBRA") -> 0 | S27: =COUNTIFS('Reporte Diario'!$H:$H,Resumen!S$23,'Reporte Diario'!$L:$L,$P27,'Reporte Diario'!$M:$M,$P$24,'Reporte Diario'!$K:$K,"OBRA") -> 0 | T27: =COUNTIFS('Reporte Diario'!$H:$H,Resumen!T$23,'Reporte Diario'!$L:$L,$P27,'Reporte Diario'!$M:$M,$P$24,'Reporte Diario'!$K:$K,"OBRA") -> 0 | U27: =COUNTIFS('Reporte Diario'!$H:$H,Resumen!U$23,'Reporte Diario'!$L:$L,$P27,'Reporte Diario'!$M:$M,$P$24,'Reporte Diario'!$K:$K,"DESCANSO") -> 0 | V27: =COUNTIFS('Reporte Diario'!$H:$H,Resumen!V$23,'Reporte Diario'!$L:$L,$P27,'Reporte Diario'!$M:$M,$P$24,'Reporte Diario'!$K:$K,"DESCANSO") -> 0 | W27: =COUNTIFS('Reporte Diario'!$H:$H,Resumen!W$23,'Reporte Diario'!$L:$L,$P27,'Reporte Diario'!$M:$M,$P$24,'Reporte Diario'!$K:$K,"DESCANSO") -> 0 | X27: =COUNTIFS('Reporte Diario'!$H:$H,Resumen!X$23,'Reporte Diario'!$L:$L,$P27,'Reporte Diario'!$M:$M,$P$24,'Reporte Diario'!$K:$K,"DESCANSO") -> 0 | Y27: =SUM(E27:M27) -> 0 | Z27: =SUM(Q27:Y27) -> 0
B28: EQUIPOS | C28: =COUNTIFS('Reporte Diario'!$K:$K,Resumen!C$9,'Reporte Diario'!$L:$L,Resumen!$B28,'Reporte Diario'!$M:$M,$B$24) -> 0 | D28: =COUNTIFS('Reporte Diario'!$K:$K,Resumen!D$9,'Reporte Diario'!$L:$L,Resumen!$B28,'Reporte Diario'!$M:$M,$B$24) -> 0 | E28: =COUNTIFS('Reporte Diario'!$K:$K,Resumen!E$9,'Reporte Diario'!$L:$L,Resumen!$B28,'Reporte Diario'!$M:$M,$B$24) -> 0 | F28: =COUNTIFS('Reporte Diario'!$K:$K,Resumen!F$9,'Reporte Diario'!$L:$L,Resumen!$B28,'Reporte Diario'!$M:$M,$B$24) -> 0 | G28: =COUNTIFS('Reporte Diario'!$K:$K,Resumen!G$9,'Reporte Diario'!$L:$L,Resumen!$B28,'Reporte Diario'!$M:$M,$B$24) -> 0 | H28: =COUNTIFS('Reporte Diario'!$K:$K,Resumen!H$9,'Reporte Diario'!$L:$L,Resumen!$B28,'Reporte Diario'!$M:$M,$B$24) -> 0 | I28: =COUNTIFS('Reporte Diario'!$K:$K,Resumen!I$9,'Reporte Diario'!$L:$L,Resumen!$B28,'Reporte Diario'!$M:$M,$B$24) -> 0 | J28: =COUNTIFS('Reporte Diario'!$K:$K,Resumen!J$9,'Reporte Diario'!$L:$L,Resumen!$B28,'Reporte Diario'!$M:$M,$B$24) -> 0 | ... M28: =COUNTIFS('Reporte Diario'!$K:$K,Resumen!M$9,'Reporte Diario'!$L:$L,Resumen!$B28,'Reporte Diario'!$M:$M,$B$24) -> 0 | N28: =SUM(C28:L28) -> 0 | P28: EQUIPOS | Q28: =COUNTIFS('Reporte Diario'!$H:$H,Resumen!Q$23,'Reporte Diario'!$L:$L,$P28,'Reporte Diario'!$M:$M,$P$24,'Reporte Diario'!$K:$K,"OBRA") -> 0 | R28: =COUNTIFS('Reporte Diario'!$H:$H,Resumen!R$23,'Reporte Diario'!$L:$L,$P28,'Reporte Diario'!$M:$M,$P$24,'Reporte Diario'!$K:$K,"OBRA") -> 0 | S28: =COUNTIFS('Reporte Diario'!$H:$H,Resumen!S$23,'Reporte Diario'!$L:$L,$P28,'Reporte Diario'!$M:$M,$P$24,'Reporte Diario'!$K:$K,"OBRA") -> 0 | T28: =COUNTIFS('Reporte Diario'!$H:$H,Resumen!T$23,'Reporte Diario'!$L:$L,$P28,'Reporte Diario'!$M:$M,$P$24,'Reporte Diario'!$K:$K,"OBRA") -> 0 | U28: =COUNTIFS('Reporte Diario'!$H:$H,Resumen!U$23,'Reporte Diario'!$L:$L,$P28,'Reporte Diario'!$M:$M,$P$24,'Reporte Diario'!$K:$K,"DESCANSO") -> 0 | V28: =COUNTIFS('Reporte Diario'!$H:$H,Resumen!V$23,'Reporte Diario'!$L:$L,$P28,'Reporte Diario'!$M:$M,$P$24,'Reporte Diario'!$K:$K,"DESCANSO") -> 0 | W28: =COUNTIFS('Reporte Diario'!$H:$H,Resumen!W$23,'Reporte Diario'!$L:$L,$P28,'Reporte Diario'!$M:$M,$P$24,'Reporte Diario'!$K:$K,"DESCANSO") -> 0 | X28: =COUNTIFS('Reporte Diario'!$H:$H,Resumen!X$23,'Reporte Diario'!$L:$L,$P28,'Reporte Diario'!$M:$M,$P$24,'Reporte Diario'!$K:$K,"DESCANSO") -> 0 | Y28: =SUM(E28:M28) -> 0 | Z28: =SUM(Q28:Y28) -> 0
B29: INGENIERIA | C29: =COUNTIFS('Reporte Diario'!$K:$K,Resumen!C$9,'Reporte Diario'!$L:$L,Resumen!$B29,'Reporte Diario'!$M:$M,$B$24) -> 0 | D29: =COUNTIFS('Reporte Diario'!$K:$K,Resumen!D$9,'Reporte Diario'!$L:$L,Resumen!$B29,'Reporte Diario'!$M:$M,$B$24) -> 0 | E29: =COUNTIFS('Reporte Diario'!$K:$K,Resumen!E$9,'Reporte Diario'!$L:$L,Resumen!$B29,'Reporte Diario'!$M:$M,$B$24) -> 0 | F29: =COUNTIFS('Reporte Diario'!$K:$K,Resumen!F$9,'Reporte Diario'!$L:$L,Resumen!$B29,'Reporte Diario'!$M:$M,$B$24) -> 0 | G29: =COUNTIFS('Reporte Diario'!$K:$K,Resumen!G$9,'Reporte Diario'!$L:$L,Resumen!$B29,'Reporte Diario'!$M:$M,$B$24) -> 0 | H29: =COUNTIFS('Reporte Diario'!$K:$K,Resumen!H$9,'Reporte Diario'!$L:$L,Resumen!$B29,'Reporte Diario'!$M:$M,$B$24) -> 0 | I29: =COUNTIFS('Reporte Diario'!$K:$K,Resumen!I$9,'Reporte Diario'!$L:$L,Resumen!$B29,'Reporte Diario'!$M:$M,$B$24) -> 0 | J29: =COUNTIFS('Reporte Diario'!$K:$K,Resumen!J$9,'Reporte Diario'!$L:$L,Resumen!$B29,'Reporte Diario'!$M:$M,$B$24) -> 0 | ... M29: =COUNTIFS('Reporte Diario'!$K:$K,Resumen!M$9,'Reporte Diario'!$L:$L,Resumen!$B29,'Reporte Diario'!$M:$M,$B$24) -> 0 | N29: =SUM(C29:L29) -> 0 | P29: INGENIERIA | Q29: =COUNTIFS('Reporte Diario'!$H:$H,Resumen!Q$23,'Reporte Diario'!$L:$L,$P29,'Reporte Diario'!$M:$M,$P$24,'Reporte Diario'!$K:$K,"OBRA") -> 0 | R29: =COUNTIFS('Reporte Diario'!$H:$H,Resumen!R$23,'Reporte Diario'!$L:$L,$P29,'Reporte Diario'!$M:$M,$P$24,'Reporte Diario'!$K:$K,"OBRA") -> 0 | S29: =COUNTIFS('Reporte Diario'!$H:$H,Resumen!S$23,'Reporte Diario'!$L:$L,$P29,'Reporte Diario'!$M:$M,$P$24,'Reporte Diario'!$K:$K,"OBRA") -> 0 | T29: =COUNTIFS('Reporte Diario'!$H:$H,Resumen!T$23,'Reporte Diario'!$L:$L,$P29,'Reporte Diario'!$M:$M,$P$24,'Reporte Diario'!$K:$K,"OBRA") -> 0 | U29: =COUNTIFS('Reporte Diario'!$H:$H,Resumen!U$23,'Reporte Diario'!$L:$L,$P29,'Reporte Diario'!$M:$M,$P$24,'Reporte Diario'!$K:$K,"DESCANSO") -> 0 | V29: =COUNTIFS('Reporte Diario'!$H:$H,Resumen!V$23,'Reporte Diario'!$L:$L,$P29,'Reporte Diario'!$M:$M,$P$24,'Reporte Diario'!$K:$K,"DESCANSO") -> 0 | W29: =COUNTIFS('Reporte Diario'!$H:$H,Resumen!W$23,'Reporte Diario'!$L:$L,$P29,'Reporte Diario'!$M:$M,$P$24,'Reporte Diario'!$K:$K,"DESCANSO") -> 0 | X29: =COUNTIFS('Reporte Diario'!$H:$H,Resumen!X$23,'Reporte Diario'!$L:$L,$P29,'Reporte Diario'!$M:$M,$P$24,'Reporte Diario'!$K:$K,"DESCANSO") -> 0 | Y29: =SUM(E29:M29) -> 0 | Z29: =SUM(Q29:Y29) -> 0
B30: MEDIO AMBIENTE | C30: =COUNTIFS('Reporte Diario'!$K:$K,Resumen!C$9,'Reporte Diario'!$L:$L,Resumen!$B30,'Reporte Diario'!$M:$M,$B$24) -> 0 | D30: =COUNTIFS('Reporte Diario'!$K:$K,Resumen!D$9,'Reporte Diario'!$L:$L,Resumen!$B30,'Reporte Diario'!$M:$M,$B$24) -> 0 | E30: =COUNTIFS('Reporte Diario'!$K:$K,Resumen!E$9,'Reporte Diario'!$L:$L,Resumen!$B30,'Reporte Diario'!$M:$M,$B$24) -> 0 | F30: =COUNTIFS('Reporte Diario'!$K:$K,Resumen!F$9,'Reporte Diario'!$L:$L,Resumen!$B30,'Reporte Diario'!$M:$M,$B$24) -> 0 | G30: =COUNTIFS('Reporte Diario'!$K:$K,Resumen!G$9,'Reporte Diario'!$L:$L,Resumen!$B30,'Reporte Diario'!$M:$M,$B$24) -> 0 | H30: =COUNTIFS('Reporte Diario'!$K:$K,Resumen!H$9,'Reporte Diario'!$L:$L,Resumen!$B30,'Reporte Diario'!$M:$M,$B$24) -> 0 | I30: =COUNTIFS('Reporte Diario'!$K:$K,Resumen!I$9,'Reporte Diario'!$L:$L,Resumen!$B30,'Reporte Diario'!$M:$M,$B$24) -> 0 | J30: =COUNTIFS('Reporte Diario'!$K:$K,Resumen!J$9,'Reporte Diario'!$L:$L,Resumen!$B30,'Reporte Diario'!$M:$M,$B$24) -> 0 | ... M30: =COUNTIFS('Reporte Diario'!$K:$K,Resumen!M$9,'Reporte Diario'!$L:$L,Resumen!$B30,'Reporte Diario'!$M:$M,$B$24) -> 0 | N30: =SUM(C30:L30) -> 0 | P30: MEDIO AMBIENTE | Q30: =COUNTIFS('Reporte Diario'!$H:$H,Resumen!Q$23,'Reporte Diario'!$L:$L,$P30,'Reporte Diario'!$M:$M,$P$24,'Reporte Diario'!$K:$K,"OBRA") -> 0 | R30: =COUNTIFS('Reporte Diario'!$H:$H,Resumen!R$23,'Reporte Diario'!$L:$L,$P30,'Reporte Diario'!$M:$M,$P$24,'Reporte Diario'!$K:$K,"OBRA") -> 0 | S30: =COUNTIFS('Reporte Diario'!$H:$H,Resumen!S$23,'Reporte Diario'!$L:$L,$P30,'Reporte Diario'!$M:$M,$P$24,'Reporte Diario'!$K:$K,"OBRA") -> 0 | T30: =COUNTIFS('Reporte Diario'!$H:$H,Resumen!T$23,'Reporte Diario'!$L:$L,$P30,'Reporte Diario'!$M:$M,$P$24,'Reporte Diario'!$K:$K,"OBRA") -> 0 | U30: =COUNTIFS('Reporte Diario'!$H:$H,Resumen!U$23,'Reporte Diario'!$L:$L,$P30,'Reporte Diario'!$M:$M,$P$24,'Reporte Diario'!$K:$K,"DESCANSO") -> 0 | V30: =COUNTIFS('Reporte Diario'!$H:$H,Resumen!V$23,'Reporte Diario'!$L:$L,$P30,'Reporte Diario'!$M:$M,$P$24,'Reporte Diario'!$K:$K,"DESCANSO") -> 0 | W30: =COUNTIFS('Reporte Diario'!$H:$H,Resumen!W$23,'Reporte Diario'!$L:$L,$P30,'Reporte Diario'!$M:$M,$P$24,'Reporte Diario'!$K:$K,"DESCANSO") -> 0 | X30: =COUNTIFS('Reporte Diario'!$H:$H,Resumen!X$23,'Reporte Diario'!$L:$L,$P30,'Reporte Diario'!$M:$M,$P$24,'Reporte Diario'!$K:$K,"DESCANSO") -> 0 | Y30: =SUM(E30:M30) -> 0 | Z30: =SUM(Q30:Y30) -> 0
B31: OFICINA CALIDAD | C31: =COUNTIFS('Reporte Diario'!$K:$K,Resumen!C$9,'Reporte Diario'!$L:$L,Resumen!$B31,'Reporte Diario'!$M:$M,$B$24) -> 0 | D31: =COUNTIFS('Reporte Diario'!$K:$K,Resumen!D$9,'Reporte Diario'!$L:$L,Resumen!$B31,'Reporte Diario'!$M:$M,$B$24) -> 0 | E31: =COUNTIFS('Reporte Diario'!$K:$K,Resumen!E$9,'Reporte Diario'!$L:$L,Resumen!$B31,'Reporte Diario'!$M:$M,$B$24) -> 0 | F31: =COUNTIFS('Reporte Diario'!$K:$K,Resumen!F$9,'Reporte Diario'!$L:$L,Resumen!$B31,'Reporte Diario'!$M:$M,$B$24) -> 0 | G31: =COUNTIFS('Reporte Diario'!$K:$K,Resumen!G$9,'Reporte Diario'!$L:$L,Resumen!$B31,'Reporte Diario'!$M:$M,$B$24) -> 0 | H31: =COUNTIFS('Reporte Diario'!$K:$K,Resumen!H$9,'Reporte Diario'!$L:$L,Resumen!$B31,'Reporte Diario'!$M:$M,$B$24) -> 0 | I31: =COUNTIFS('Reporte Diario'!$K:$K,Resumen!I$9,'Reporte Diario'!$L:$L,Resumen!$B31,'Reporte Diario'!$M:$M,$B$24) -> 0 | J31: =COUNTIFS('Reporte Diario'!$K:$K,Resumen!J$9,'Reporte Diario'!$L:$L,Resumen!$B31,'Reporte Diario'!$M:$M,$B$24) -> 0 | ... M31: =COUNTIFS('Reporte Diario'!$K:$K,Resumen!M$9,'Reporte Diario'!$L:$L,Resumen!$B31,'Reporte Diario'!$M:$M,$B$24) -> 0 | N31: =SUM(C31:L31) -> 0 | P31: OFICINA CALIDAD | Q31: =COUNTIFS('Reporte Diario'!$H:$H,Resumen!Q$23,'Reporte Diario'!$L:$L,$P31,'Reporte Diario'!$M:$M,$P$24,'Reporte Diario'!$K:$K,"OBRA") -> 0 | R31: =COUNTIFS('Reporte Diario'!$H:$H,Resumen!R$23,'Reporte Diario'!$L:$L,$P31,'Reporte Diario'!$M:$M,$P$24,'Reporte Diario'!$K:$K,"OBRA") -> 0 | S31: =COUNTIFS('Reporte Diario'!$H:$H,Resumen!S$23,'Reporte Diario'!$L:$L,$P31,'Reporte Diario'!$M:$M,$P$24,'Reporte Diario'!$K:$K,"OBRA") -> 0 | T31: =COUNTIFS('Reporte Diario'!$H:$H,Resumen!T$23,'Reporte Diario'!$L:$L,$P31,'Reporte Diario'!$M:$M,$P$24,'Reporte Diario'!$K:$K,"OBRA") -> 0 | U31: =COUNTIFS('Reporte Diario'!$H:$H,Resumen!U$23,'Reporte Diario'!$L:$L,$P31,'Reporte Diario'!$M:$M,$P$24,'Reporte Diario'!$K:$K,"DESCANSO") -> 0 | V31: =COUNTIFS('Reporte Diario'!$H:$H,Resumen!V$23,'Reporte Diario'!$L:$L,$P31,'Reporte Diario'!$M:$M,$P$24,'Reporte Diario'!$K:$K,"DESCANSO") -> 0 | W31: =COUNTIFS('Reporte Diario'!$H:$H,Resumen!W$23,'Reporte Diario'!$L:$L,$P31,'Reporte Diario'!$M:$M,$P$24,'Reporte Diario'!$K:$K,"DESCANSO") -> 0 | X31: =COUNTIFS('Reporte Diario'!$H:$H,Resumen!X$23,'Reporte Diario'!$L:$L,$P31,'Reporte Diario'!$M:$M,$P$24,'Reporte Diario'!$K:$K,"DESCANSO") -> 0 | Y31: =SUM(E31:M31) -> 0 | Z31: =SUM(Q31:Y31) -> 0
B32: OFICINA TECNICA | C32: =COUNTIFS('Reporte Diario'!$K:$K,Resumen!C$9,'Reporte Diario'!$L:$L,Resumen!$B32,'Reporte Diario'!$M:$M,$B$24) -> 0 | D32: =COUNTIFS('Reporte Diario'!$K:$K,Resumen!D$9,'Reporte Diario'!$L:$L,Resumen!$B32,'Reporte Diario'!$M:$M,$B$24) -> 0 | E32: =COUNTIFS('Reporte Diario'!$K:$K,Resumen!E$9,'Reporte Diario'!$L:$L,Resumen!$B32,'Reporte Diario'!$M:$M,$B$24) -> 0 | F32: =COUNTIFS('Reporte Diario'!$K:$K,Resumen!F$9,'Reporte Diario'!$L:$L,Resumen!$B32,'Reporte Diario'!$M:$M,$B$24) -> 0 | G32: =COUNTIFS('Reporte Diario'!$K:$K,Resumen!G$9,'Reporte Diario'!$L:$L,Resumen!$B32,'Reporte Diario'!$M:$M,$B$24) -> 0 | H32: =COUNTIFS('Reporte Diario'!$K:$K,Resumen!H$9,'Reporte Diario'!$L:$L,Resumen!$B32,'Reporte Diario'!$M:$M,$B$24) -> 0 | I32: =COUNTIFS('Reporte Diario'!$K:$K,Resumen!I$9,'Reporte Diario'!$L:$L,Resumen!$B32,'Reporte Diario'!$M:$M,$B$24) -> 0 | J32: =COUNTIFS('Reporte Diario'!$K:$K,Resumen!J$9,'Reporte Diario'!$L:$L,Resumen!$B32,'Reporte Diario'!$M:$M,$B$24) -> 0 | ... M32: =COUNTIFS('Reporte Diario'!$K:$K,Resumen!M$9,'Reporte Diario'!$L:$L,Resumen!$B32,'Reporte Diario'!$M:$M,$B$24) -> 0 | N32: =SUM(C32:L32) -> 0 | P32: OFICINA TECNICA | Q32: =COUNTIFS('Reporte Diario'!$H:$H,Resumen!Q$23,'Reporte Diario'!$L:$L,$P32,'Reporte Diario'!$M:$M,$P$24,'Reporte Diario'!$K:$K,"OBRA") -> 0 | R32: =COUNTIFS('Reporte Diario'!$H:$H,Resumen!R$23,'Reporte Diario'!$L:$L,$P32,'Reporte Diario'!$M:$M,$P$24,'Reporte Diario'!$K:$K,"OBRA") -> 0 | S32: =COUNTIFS('Reporte Diario'!$H:$H,Resumen!S$23,'Reporte Diario'!$L:$L,$P32,'Reporte Diario'!$M:$M,$P$24,'Reporte Diario'!$K:$K,"OBRA") -> 0 | T32: =COUNTIFS('Reporte Diario'!$H:$H,Resumen!T$23,'Reporte Diario'!$L:$L,$P32,'Reporte Diario'!$M:$M,$P$24,'Reporte Diario'!$K:$K,"OBRA") -> 0 | U32: =COUNTIFS('Reporte Diario'!$H:$H,Resumen!U$23,'Reporte Diario'!$L:$L,$P32,'Reporte Diario'!$M:$M,$P$24,'Reporte Diario'!$K:$K,"DESCANSO") -> 0 | V32: =COUNTIFS('Reporte Diario'!$H:$H,Resumen!V$23,'Reporte Diario'!$L:$L,$P32,'Reporte Diario'!$M:$M,$P$24,'Reporte Diario'!$K:$K,"DESCANSO") -> 0 | W32: =COUNTIFS('Reporte Diario'!$H:$H,Resumen!W$23,'Reporte Diario'!$L:$L,$P32,'Reporte Diario'!$M:$M,$P$24,'Reporte Diario'!$K:$K,"DESCANSO") -> 0 | X32: =COUNTIFS('Reporte Diario'!$H:$H,Resumen!X$23,'Reporte Diario'!$L:$L,$P32,'Reporte Diario'!$M:$M,$P$24,'Reporte Diario'!$K:$K,"DESCANSO") -> 0 | Y32: =SUM(E32:M32) -> 0 | Z32: =SUM(Q32:Y32) -> 0
B33: PREVENCION DE RIESGOS | C33: =COUNTIFS('Reporte Diario'!$K:$K,Resumen!C$9,'Reporte Diario'!$L:$L,Resumen!$B33,'Reporte Diario'!$M:$M,$B$24) -> 0 | D33: =COUNTIFS('Reporte Diario'!$K:$K,Resumen!D$9,'Reporte Diario'!$L:$L,Resumen!$B33,'Reporte Diario'!$M:$M,$B$24) -> 0 | E33: =COUNTIFS('Reporte Diario'!$K:$K,Resumen!E$9,'Reporte Diario'!$L:$L,Resumen!$B33,'Reporte Diario'!$M:$M,$B$24) -> 0 | F33: =COUNTIFS('Reporte Diario'!$K:$K,Resumen!F$9,'Reporte Diario'!$L:$L,Resumen!$B33,'Reporte Diario'!$M:$M,$B$24) -> 0 | G33: =COUNTIFS('Reporte Diario'!$K:$K,Resumen!G$9,'Reporte Diario'!$L:$L,Resumen!$B33,'Reporte Diario'!$M:$M,$B$24) -> 0 | H33: =COUNTIFS('Reporte Diario'!$K:$K,Resumen!H$9,'Reporte Diario'!$L:$L,Resumen!$B33,'Reporte Diario'!$M:$M,$B$24) -> 0 | I33: =COUNTIFS('Reporte Diario'!$K:$K,Resumen!I$9,'Reporte Diario'!$L:$L,Resumen!$B33,'Reporte Diario'!$M:$M,$B$24) -> 0 | J33: =COUNTIFS('Reporte Diario'!$K:$K,Resumen!J$9,'Reporte Diario'!$L:$L,Resumen!$B33,'Reporte Diario'!$M:$M,$B$24) -> 0 | ... M33: =COUNTIFS('Reporte Diario'!$K:$K,Resumen!M$9,'Reporte Diario'!$L:$L,Resumen!$B33,'Reporte Diario'!$M:$M,$B$24) -> 0 | N33: =SUM(C33:L33) -> 0 | P33: PREVENCION DE RIESGOS | Q33: =COUNTIFS('Reporte Diario'!$H:$H,Resumen!Q$23,'Reporte Diario'!$L:$L,$P33,'Reporte Diario'!$M:$M,$P$24,'Reporte Diario'!$K:$K,"OBRA") -> 0 | R33: =COUNTIFS('Reporte Diario'!$H:$H,Resumen!R$23,'Reporte Diario'!$L:$L,$P33,'Reporte Diario'!$M:$M,$P$24,'Reporte Diario'!$K:$K,"OBRA") -> 0 | S33: =COUNTIFS('Reporte Diario'!$H:$H,Resumen!S$23,'Reporte Diario'!$L:$L,$P33,'Reporte Diario'!$M:$M,$P$24,'Reporte Diario'!$K:$K,"OBRA") -> 0 | T33: =COUNTIFS('Reporte Diario'!$H:$H,Resumen!T$23,'Reporte Diario'!$L:$L,$P33,'Reporte Diario'!$M:$M,$P$24,'Reporte Diario'!$K:$K,"OBRA") -> 0 | U33: =COUNTIFS('Reporte Diario'!$H:$H,Resumen!U$23,'Reporte Diario'!$L:$L,$P33,'Reporte Diario'!$M:$M,$P$24,'Reporte Diario'!$K:$K,"DESCANSO") -> 0 | V33: =COUNTIFS('Reporte Diario'!$H:$H,Resumen!V$23,'Reporte Diario'!$L:$L,$P33,'Reporte Diario'!$M:$M,$P$24,'Reporte Diario'!$K:$K,"DESCANSO") -> 0 | W33: =COUNTIFS('Reporte Diario'!$H:$H,Resumen!W$23,'Reporte Diario'!$L:$L,$P33,'Reporte Diario'!$M:$M,$P$24,'Reporte Diario'!$K:$K,"DESCANSO") -> 0 | X33: =COUNTIFS('Reporte Diario'!$H:$H,Resumen!X$23,'Reporte Diario'!$L:$L,$P33,'Reporte Diario'!$M:$M,$P$24,'Reporte Diario'!$K:$K,"DESCANSO") -> 0 | Y33: =SUM(E33:M33) -> 0 | Z33: =SUM(Q33:Y33) -> 0
B34: STAFF SUPERIOR | C34: =COUNTIFS('Reporte Diario'!$K:$K,Resumen!C$9,'Reporte Diario'!$L:$L,Resumen!$B34,'Reporte Diario'!$M:$M,$B$24) -> 0 | D34: =COUNTIFS('Reporte Diario'!$K:$K,Resumen!D$9,'Reporte Diario'!$L:$L,Resumen!$B34,'Reporte Diario'!$M:$M,$B$24) -> 0 | E34: =COUNTIFS('Reporte Diario'!$K:$K,Resumen!E$9,'Reporte Diario'!$L:$L,Resumen!$B34,'Reporte Diario'!$M:$M,$B$24) -> 0 | F34: =COUNTIFS('Reporte Diario'!$K:$K,Resumen!F$9,'Reporte Diario'!$L:$L,Resumen!$B34,'Reporte Diario'!$M:$M,$B$24) -> 0 | G34: =COUNTIFS('Reporte Diario'!$K:$K,Resumen!G$9,'Reporte Diario'!$L:$L,Resumen!$B34,'Reporte Diario'!$M:$M,$B$24) -> 0 | H34: =COUNTIFS('Reporte Diario'!$K:$K,Resumen!H$9,'Reporte Diario'!$L:$L,Resumen!$B34,'Reporte Diario'!$M:$M,$B$24) -> 0 | I34: =COUNTIFS('Reporte Diario'!$K:$K,Resumen!I$9,'Reporte Diario'!$L:$L,Resumen!$B34,'Reporte Diario'!$M:$M,$B$24) -> 0 | J34: =COUNTIFS('Reporte Diario'!$K:$K,Resumen!J$9,'Reporte Diario'!$L:$L,Resumen!$B34,'Reporte Diario'!$M:$M,$B$24) -> 0 | ... M34: =COUNTIFS('Reporte Diario'!$K:$K,Resumen!M$9,'Reporte Diario'!$L:$L,Resumen!$B34,'Reporte Diario'!$M:$M,$B$24) -> 0 | N34: =SUM(C34:L34) -> 0 | P34: STAFF SUPERIOR | Q34: =COUNTIFS('Reporte Diario'!$H:$H,Resumen!Q$23,'Reporte Diario'!$L:$L,$P34,'Reporte Diario'!$M:$M,$P$24,'Reporte Diario'!$K:$K,"OBRA") -> 0 | R34: =COUNTIFS('Reporte Diario'!$H:$H,Resumen!R$23,'Reporte Diario'!$L:$L,$P34,'Reporte Diario'!$M:$M,$P$24,'Reporte Diario'!$K:$K,"OBRA") -> 0 | S34: =COUNTIFS('Reporte Diario'!$H:$H,Resumen!S$23,'Reporte Diario'!$L:$L,$P34,'Reporte Diario'!$M:$M,$P$24,'Reporte Diario'!$K:$K,"OBRA") -> 0 | T34: =COUNTIFS('Reporte Diario'!$H:$H,Resumen!T$23,'Reporte Diario'!$L:$L,$P34,'Reporte Diario'!$M:$M,$P$24,'Reporte Diario'!$K:$K,"OBRA") -> 0 | U34: =COUNTIFS('Reporte Diario'!$H:$H,Resumen!U$23,'Reporte Diario'!$L:$L,$P34,'Reporte Diario'!$M:$M,$P$24,'Reporte Diario'!$K:$K,"DESCANSO") -> 0 | V34: =COUNTIFS('Reporte Diario'!$H:$H,Resumen!V$23,'Reporte Diario'!$L:$L,$P34,'Reporte Diario'!$M:$M,$P$24,'Reporte Diario'!$K:$K,"DESCANSO") -> 0 | W34: =COUNTIFS('Reporte Diario'!$H:$H,Resumen!W$23,'Reporte Diario'!$L:$L,$P34,'Reporte Diario'!$M:$M,$P$24,'Reporte Diario'!$K:$K,"DESCANSO") -> 0 | X34: =COUNTIFS('Reporte Diario'!$H:$H,Resumen!X$23,'Reporte Diario'!$L:$L,$P34,'Reporte Diario'!$M:$M,$P$24,'Reporte Diario'!$K:$K,"DESCANSO") -> 0 | Y34: =SUM(E34:M34) -> 0 | Z34: =SUM(Q34:Y34) -> 0
B35: SECRETARIO TECNICO | C35: =COUNTIFS('Reporte Diario'!$K:$K,Resumen!C$9,'Reporte Diario'!$L:$L,Resumen!$B35,'Reporte Diario'!$M:$M,$B$24) -> 0 | D35: =COUNTIFS('Reporte Diario'!$K:$K,Resumen!D$9,'Reporte Diario'!$L:$L,Resumen!$B35,'Reporte Diario'!$M:$M,$B$24) -> 0 | E35: =COUNTIFS('Reporte Diario'!$K:$K,Resumen!E$9,'Reporte Diario'!$L:$L,Resumen!$B35,'Reporte Diario'!$M:$M,$B$24) -> 0 | F35: =COUNTIFS('Reporte Diario'!$K:$K,Resumen!F$9,'Reporte Diario'!$L:$L,Resumen!$B35,'Reporte Diario'!$M:$M,$B$24) -> 0 | G35: =COUNTIFS('Reporte Diario'!$K:$K,Resumen!G$9,'Reporte Diario'!$L:$L,Resumen!$B35,'Reporte Diario'!$M:$M,$B$24) -> 0 | H35: =COUNTIFS('Reporte Diario'!$K:$K,Resumen!H$9,'Reporte Diario'!$L:$L,Resumen!$B35,'Reporte Diario'!$M:$M,$B$24) -> 0 | I35: =COUNTIFS('Reporte Diario'!$K:$K,Resumen!I$9,'Reporte Diario'!$L:$L,Resumen!$B35,'Reporte Diario'!$M:$M,$B$24) -> 0 | J35: =COUNTIFS('Reporte Diario'!$K:$K,Resumen!J$9,'Reporte Diario'!$L:$L,Resumen!$B35,'Reporte Diario'!$M:$M,$B$24) -> 0 | ... M35: =COUNTIFS('Reporte Diario'!$K:$K,Resumen!M$9,'Reporte Diario'!$L:$L,Resumen!$B35,'Reporte Diario'!$M:$M,$B$24) -> 0 | N35: =SUM(C35:L35) -> 0 | P35: SECRETARIO TECNICO | Q35: =COUNTIFS('Reporte Diario'!$H:$H,Resumen!Q$23,'Reporte Diario'!$L:$L,$P35,'Reporte Diario'!$M:$M,$P$24,'Reporte Diario'!$K:$K,"OBRA") -> 0 | R35: =COUNTIFS('Reporte Diario'!$H:$H,Resumen!R$23,'Reporte Diario'!$L:$L,$P35,'Reporte Diario'!$M:$M,$P$24,'Reporte Diario'!$K:$K,"OBRA") -> 0 | S35: =COUNTIFS('Reporte Diario'!$H:$H,Resumen!S$23,'Reporte Diario'!$L:$L,$P35,'Reporte Diario'!$M:$M,$P$24,'Reporte Diario'!$K:$K,"OBRA") -> 0 | T35: =COUNTIFS('Reporte Diario'!$H:$H,Resumen!T$23,'Reporte Diario'!$L:$L,$P35,'Reporte Diario'!$M:$M,$P$24,'Reporte Diario'!$K:$K,"OBRA") -> 0 | U35: =COUNTIFS('Reporte Diario'!$H:$H,Resumen!U$23,'Reporte Diario'!$L:$L,$P35,'Reporte Diario'!$M:$M,$P$24,'Reporte Diario'!$K:$K,"DESCANSO") -> 0 | V35: =COUNTIFS('Reporte Diario'!$H:$H,Resumen!V$23,'Reporte Diario'!$L:$L,$P35,'Reporte Diario'!$M:$M,$P$24,'Reporte Diario'!$K:$K,"DESCANSO") -> 0 | W35: =COUNTIFS('Reporte Diario'!$H:$H,Resumen!W$23,'Reporte Diario'!$L:$L,$P35,'Reporte Diario'!$M:$M,$P$24,'Reporte Diario'!$K:$K,"DESCANSO") -> 0 | X35: =COUNTIFS('Reporte Diario'!$H:$H,Resumen!X$23,'Reporte Diario'!$L:$L,$P35,'Reporte Diario'!$M:$M,$P$24,'Reporte Diario'!$K:$K,"DESCANSO") -> 0 | Y35: =SUM(E35:M35) -> 0 | Z35: =SUM(Q35:Y35) -> 0
B36: SERVICIOS | C36: =COUNTIFS('Reporte Diario'!$K:$K,Resumen!C$9,'Reporte Diario'!$L:$L,Resumen!$B36,'Reporte Diario'!$M:$M,$B$24) -> 0 | D36: =COUNTIFS('Reporte Diario'!$K:$K,Resumen!D$9,'Reporte Diario'!$L:$L,Resumen!$B36,'Reporte Diario'!$M:$M,$B$24) -> 0 | E36: =COUNTIFS('Reporte Diario'!$K:$K,Resumen!E$9,'Reporte Diario'!$L:$L,Resumen!$B36,'Reporte Diario'!$M:$M,$B$24) -> 0 | F36: =COUNTIFS('Reporte Diario'!$K:$K,Resumen!F$9,'Reporte Diario'!$L:$L,Resumen!$B36,'Reporte Diario'!$M:$M,$B$24) -> 0 | G36: =COUNTIFS('Reporte Diario'!$K:$K,Resumen!G$9,'Reporte Diario'!$L:$L,Resumen!$B36,'Reporte Diario'!$M:$M,$B$24) -> 0 | H36: =COUNTIFS('Reporte Diario'!$K:$K,Resumen!H$9,'Reporte Diario'!$L:$L,Resumen!$B36,'Reporte Diario'!$M:$M,$B$24) -> 0 | I36: =COUNTIFS('Reporte Diario'!$K:$K,Resumen!I$9,'Reporte Diario'!$L:$L,Resumen!$B36,'Reporte Diario'!$M:$M,$B$24) -> 0 | J36: =COUNTIFS('Reporte Diario'!$K:$K,Resumen!J$9,'Reporte Diario'!$L:$L,Resumen!$B36,'Reporte Diario'!$M:$M,$B$24) -> 0 | ... M36: =COUNTIFS('Reporte Diario'!$K:$K,Resumen!M$9,'Reporte Diario'!$L:$L,Resumen!$B36,'Reporte Diario'!$M:$M,$B$24) -> 0 | N36: =SUM(C36:L36) -> 0 | P36: SERVICIOS | Q36: =COUNTIFS('Reporte Diario'!$H:$H,Resumen!Q$23,'Reporte Diario'!$L:$L,$P36,'Reporte Diario'!$M:$M,$P$24,'Reporte Diario'!$K:$K,"OBRA") -> 0 | R36: =COUNTIFS('Reporte Diario'!$H:$H,Resumen!R$23,'Reporte Diario'!$L:$L,$P36,'Reporte Diario'!$M:$M,$P$24,'Reporte Diario'!$K:$K,"OBRA") -> 0 | S36: =COUNTIFS('Reporte Diario'!$H:$H,Resumen!S$23,'Reporte Diario'!$L:$L,$P36,'Reporte Diario'!$M:$M,$P$24,'Reporte Diario'!$K:$K,"OBRA") -> 0 | T36: =COUNTIFS('Reporte Diario'!$H:$H,Resumen!T$23,'Reporte Diario'!$L:$L,$P36,'Reporte Diario'!$M:$M,$P$24,'Reporte Diario'!$K:$K,"OBRA") -> 0 | U36: =COUNTIFS('Reporte Diario'!$H:$H,Resumen!U$23,'Reporte Diario'!$L:$L,$P36,'Reporte Diario'!$M:$M,$P$24,'Reporte Diario'!$K:$K,"DESCANSO") -> 0 | V36: =COUNTIFS('Reporte Diario'!$H:$H,Resumen!V$23,'Reporte Diario'!$L:$L,$P36,'Reporte Diario'!$M:$M,$P$24,'Reporte Diario'!$K:$K,"DESCANSO") -> 0 | W36: =COUNTIFS('Reporte Diario'!$H:$H,Resumen!W$23,'Reporte Diario'!$L:$L,$P36,'Reporte Diario'!$M:$M,$P$24,'Reporte Diario'!$K:$K,"DESCANSO") -> 0 | X36: =COUNTIFS('Reporte Diario'!$H:$H,Resumen!X$23,'Reporte Diario'!$L:$L,$P36,'Reporte Diario'!$M:$M,$P$24,'Reporte Diario'!$K:$K,"DESCANSO") -> 0 | Y36: =SUM(E36:M36) -> 0 | Z36: =SUM(Q36:Y36) -> 0
